Workbook

Sheet 1.1
A1: Reg.No | B1: Name | C1: IT1134 | D1: IT1144 | E1: IT1113 | F1: IT1122 | G1: IT1152 | H1: GPA
A2: 2020/ICT/01 | B2: Ms. Udisha W.H.I | C2: B+ | D2: B+ | E2: A- | F2: B | G2: B- | H2: =IFERROR( ROUND( ( (IF(C2="A+", 4, IF(C2="A", 4, IF(C2="A-", 3.7, IF(C2="B+", 3.3, IF(C2="B", 3, IF(C2="B-", 2.7, IF(C2="C+", 2.3, IF(C2="C", 2, IF(C2="C-", 1.7, IF(C2="D+", 1.3, IF(C2="D", 1, IF(C2="E", 0, 0)))))))))))) * 4) + (IF(D2="A+", 4, IF(D2="A", 4, IF(D2="A-", 3.7, IF(D2="B+", 3.3, IF(D2="B", 3, IF(D2="B-", 2.7, IF(D2="C+", 2.3, IF(D2="C", 2, IF(D2="C-", 1.7, IF(D2="D+", 1.3, IF(D2="D", 1, IF(D2="E", 0, 0)))))))))))) * 4) + (IF(E2="A+", 4, IF(E2="A", 4, IF(E2="A-", 3.7, IF(E2="B+", 3.3, IF(E2="B", 3, IF(E2="B-", 2.7, IF(E2="C+", 2.3, IF(E2="C", 2, IF(E2="C-", 1.7, IF(E2="D+", 1.3, IF(E2="D", 1, IF(E2="E", 0, 0)))))))))))) * 3) + (IF(F2="A+", 4, IF(F2="A", 4, IF(F2="A-", 3.7, IF(F2="B+", 3.3, IF(F2="B", 3, IF(F2="B-", 2.7, IF(F2="C+", 2.3, IF(F2="C", 2, IF(F2="C-", 1.7, IF(F2="D+", 1.3, IF(F2="D", 1, IF(F2="E", 0, 0)))))))))))) * 2) + (IF(G2="A+", 4, IF(G2="A", 4, IF(G2="A-", 3.7, IF(G2="B+", 3.3, IF(G2="B", 3, IF(G2="B-", 2.7, IF(G2="C+", 2.3, IF(G2="C", 2, IF(G2="C-", 1.7, IF(G2="D+", 1.3, IF(G2="D", 1, IF(G2="E", 0, 0)))))))))))) * 2) ) / (4 + 4 + 3 + 2 + 2), 2), 0) -> 3.26
A3: 2020/ICT/02 | B3: Mr. Imran B.M. | C3: C- | D3: B | E3: B | F3: C- | G3: absent | H3: =IFERROR( ROUND( ( (IF(C3="A+", 4, IF(C3="A", 4, IF(C3="A-", 3.7, IF(C3="B+", 3.3, IF(C3="B", 3, IF(C3="B-", 2.7, IF(C3="C+", 2.3, IF(C3="C", 2, IF(C3="C-", 1.7, IF(C3="D+", 1.3, IF(C3="D", 1, IF(C3="E", 0, 0)))))))))))) * 4) + (IF(D3="A+", 4, IF(D3="A", 4, IF(D3="A-", 3.7, IF(D3="B+", 3.3, IF(D3="B", 3, IF(D3="B-", 2.7, IF(D3="C+", 2.3, IF(D3="C", 2, IF(D3="C-", 1.7, IF(D3="D+", 1.3, IF(D3="D", 1, IF(D3="E", 0, 0)))))))))))) * 4) + (IF(E3="A+", 4, IF(E3="A", 4, IF(E3="A-", 3.7, IF(E3="B+", 3.3, IF(E3="B", 3, IF(E3="B-", 2.7, IF(E3="C+", 2.3, IF(E3="C", 2, IF(E3="C-", 1.7, IF(E3="D+", 1.3, IF(E3="D", 1, IF(E3="E", 0, 0)))))))))))) * 3) + (IF(F3="A+", 4, IF(F3="A", 4, IF(F3="A-", 3.7, IF(F3="B+", 3.3, IF(F3="B", 3, IF(F3="B-", 2.7, IF(F3="C+", 2.3, IF(F3="C", 2, IF(F3="C-", 1.7, IF(F3="D+", 1.3, IF(F3="D", 1, IF(F3="E", 0, 0)))))))))))) * 2) + (IF(G3="A+", 4, IF(G3="A", 4, IF(G3="A-", 3.7, IF(G3="B+", 3.3, IF(G3="B", 3, IF(G3="B-", 2.7, IF(G3="C+", 2.3, IF(G3="C", 2, IF(G3="C-", 1.7, IF(G3="D+", 1.3, IF(G3="D", 1, IF(G3="E", 0, 0)))))))))))) * 2) ) / (4 + 4 + 3 + 2 + 2), 2), 0) -> 2.08
A4: 2020/ICT/03 | B4: Ms. Shanmugarajah D. | C4: B+ | D4: A- | E4: B+ | F4: A | G4: A- | H4: =IFERROR( ROUND( ( (IF(C4="A+", 4, IF(C4="A", 4, IF(C4="A-", 3.7, IF(C4="B+", 3.3, IF(C4="B", 3, IF(C4="B-", 2.7, IF(C4="C+", 2.3, IF(C4="C", 2, IF(C4="C-", 1.7, IF(C4="D+", 1.3, IF(C4="D", 1, IF(C4="E", 0, 0)))))))))))) * 4) + (IF(D4="A+", 4, IF(D4="A", 4, IF(D4="A-", 3.7, IF(D4="B+", 3.3, IF(D4="B", 3, IF(D4="B-", 2.7, IF(D4="C+", 2.3, IF(D4="C", 2, IF(D4="C-", 1.7, IF(D4="D+", 1.3, IF(D4="D", 1, IF(D4="E", 0, 0)))))))))))) * 4) + (IF(E4="A+", 4, IF(E4="A", 4, IF(E4="A-", 3.7, IF(E4="B+", 3.3, IF(E4="B", 3, IF(E4="B-", 2.7, IF(E4="C+", 2.3, IF(E4="C", 2, IF(E4="C-", 1.7, IF(E4="D+", 1.3, IF(E4="D", 1, IF(E4="E", 0, 0)))))))))))) * 3) + (IF(F4="A+", 4, IF(F4="A", 4, IF(F4="A-", 3.7, IF(F4="B+", 3.3, IF(F4="B", 3, IF(F4="B-", 2.7, IF(F4="C+", 2.3, IF(F4="C", 2, IF(F4="C-", 1.7, IF(F4="D+", 1.3, IF(F4="D", 1, IF(F4="E", 0, 0)))))))))))) * 2) + (IF(G4="A+", 4, IF(G4="A", 4, IF(G4="A-", 3.7, IF(G4="B+", 3.3, IF(G4="B", 3, IF(G4="B-", 2.7, IF(G4="C+", 2.3, IF(G4="C", 2, IF(G4="C-", 1.7, IF(G4="D+", 1.3, IF(G4="D", 1, IF(G4="E", 0, 0)))))))))))) * 2) ) / (4 + 4 + 3 + 2 + 2), 2), 0) -> 3.55
A5: 2020/ICT/05 | B5: Mr. Muniweera K.G.U.K. | C5: B+ | D5: A+ | E5: A- | F5: B | G5: C- | H5: =IFERROR( ROUND( ( (IF(C5="A+", 4, IF(C5="A", 4, IF(C5="A-", 3.7, IF(C5="B+", 3.3, IF(C5="B", 3, IF(C5="B-", 2.7, IF(C5="C+", 2.3, IF(C5="C", 2, IF(C5="C-", 1.7, IF(C5="D+", 1.3, IF(C5="D", 1, IF(C5="E", 0, 0)))))))))))) * 4) + (IF(D5="A+", 4, IF(D5="A", 4, IF(D5="A-", 3.7, IF(D5="B+", 3.3, IF(D5="B", 3, IF(D5="B-", 2.7, IF(D5="C+", 2.3, IF(D5="C", 2, IF(D5="C-", 1.7, IF(D5="D+", 1.3, IF(D5="D", 1, IF(D5="E", 0, 0)))))))))))) * 4) + (IF(E5="A+", 4, IF(E5="A", 4, IF(E5="A-", 3.7, IF(E5="B+", 3.3, IF(E5="B", 3, IF(E5="B-", 2.7, IF(E5="C+", 2.3, IF(E5="C", 2, IF(E5="C-", 1.7, IF(E5="D+", 1.3, IF(E5="D", 1, IF(E5="E", 0, 0)))))))))))) * 3) + (IF(F5="A+", 4, IF(F5="A", 4, IF(F5="A-", 3.7, IF(F5="B+", 3.3, IF(F5="B", 3, IF(F5="B-", 2.7, IF(F5="C+", 2.3, IF(F5="C", 2, IF(F5="C-", 1.7, IF(F5="D+", 1.3, IF(F5="D", 1, IF(F5="E", 0, 0)))))))))))) * 2) + (IF(G5="A+", 4, IF(G5="A", 4, IF(G5="A-", 3.7, IF(G5="B+", 3.3, IF(G5="B", 3, IF(G5="B-", 2.7, IF(G5="C+", 2.3, IF(G5="C", 2, IF(G5="C-", 1.7, IF(G5="D+", 1.3, IF(G5="D", 1, IF(G5="E", 0, 0)))))))))))) * 2) ) / (4 + 4 + 3 + 2 + 2), 2), 0) -> 3.31
A6: 2020/ICT/06 | B6: Ms. Lourdes Jellorine | C6: A+ | D6: A+ | E6: A | F6: A+ | G6: A+ | H6: =IFERROR( ROUND( ( (IF(C6="A+", 4, IF(C6="A", 4, IF(C6="A-", 3.7, IF(C6="B+", 3.3, IF(C6="B", 3, IF(C6="B-", 2.7, IF(C6="C+", 2.3, IF(C6="C", 2, IF(C6="C-", 1.7, IF(C6="D+", 1.3, IF(C6="D", 1, IF(C6="E", 0, 0)))))))))))) * 4) + (IF(D6="A+", 4, IF(D6="A", 4, IF(D6="A-", 3.7, IF(D6="B+", 3.3, IF(D6="B", 3, IF(D6="B-", 2.7, IF(D6="C+", 2.3, IF(D6="C", 2, IF(D6="C-", 1.7, IF(D6="D+", 1.3, IF(D6="D", 1, IF(D6="E", 0, 0)))))))))))) * 4) + (IF(E6="A+", 4, IF(E6="A", 4, IF(E6="A-", 3.7, IF(E6="B+", 3.3, IF(E6="B", 3, IF(E6="B-", 2.7, IF(E6="C+", 2.3, IF(E6="C", 2, IF(E6="C-", 1.7, IF(E6="D+", 1.3, IF(E6="D", 1, IF(E6="E", 0, 0)))))))))))) * 3) + (IF(F6="A+", 4, IF(F6="A", 4, IF(F6="A-", 3.7, IF(F6="B+", 3.3, IF(F6="B", 3, IF(F6="B-", 2.7, IF(F6="C+", 2.3, IF(F6="C", 2, IF(F6="C-", 1.7, IF(F6="D+", 1.3, IF(F6="D", 1, IF(F6="E", 0, 0)))))))))))) * 2) + (IF(G6="A+", 4, IF(G6="A", 4, IF(G6="A-", 3.7, IF(G6="B+", 3.3, IF(G6="B", 3, IF(G6="B-", 2.7, IF(G6="C+", 2.3, IF(G6="C", 2, IF(G6="C-", 1.7, IF(G6="D+", 1.3, IF(G6="D", 1, IF(G6="E", 0, 0)))))))))))) * 2) ) / (4 + 4 + 3 + 2 + 2), 2), 0) -> 4
A7: 2020/ICT/07 | B7: Mr. Nalawansa U.K | C7: A | D7: A+ | E7: A | F7: A+ | G7: A+ | H7: =IFERROR( ROUND( ( (IF(C7="A+", 4, IF(C7="A", 4, IF(C7="A-", 3.7, IF(C7="B+", 3.3, IF(C7="B", 3, IF(C7="B-", 2.7, IF(C7="C+", 2.3, IF(C7="C", 2, IF(C7="C-", 1.7, IF(C7="D+", 1.3, IF(C7="D", 1, IF(C7="E", 0, 0)))))))))))) * 4) + (IF(D7="A+", 4, IF(D7="A", 4, IF(D7="A-", 3.7, IF(D7="B+", 3.3, IF(D7="B", 3, IF(D7="B-", 2.7, IF(D7="C+", 2.3, IF(D7="C", 2, IF(D7="C-", 1.7, IF(D7="D+", 1.3, IF(D7="D", 1, IF(D7="E", 0, 0)))))))))))) * 4) + (IF(E7="A+", 4, IF(E7="A", 4, IF(E7="A-", 3.7, IF(E7="B+", 3.3, IF(E7="B", 3, IF(E7="B-", 2.7, IF(E7="C+", 2.3, IF(E7="C", 2, IF(E7="C-", 1.7, IF(E7="D+", 1.3, IF(E7="D", 1, IF(E7="E", 0, 0)))))))))))) * 3) + (IF(F7="A+", 4, IF(F7="A", 4, IF(F7="A-", 3.7, IF(F7="B+", 3.3, IF(F7="B", 3, IF(F7="B-", 2.7, IF(F7="C+", 2.3, IF(F7="C", 2, IF(F7="C-", 1.7, IF(F7="D+", 1.3, IF(F7="D", 1, IF(F7="E", 0, 0)))))))))))) * 2) + (IF(G7="A+", 4, IF(G7="A", 4, IF(G7="A-", 3.7, IF(G7="B+", 3.3, IF(G7="B", 3, IF(G7="B-", 2.7, IF(G7="C+", 2.3, IF(G7="C", 2, IF(G7="C-", 1.7, IF(G7="D+", 1.3, IF(G7="D", 1, IF(G7="E", 0, 0)))))))))))) * 2) ) / (4 + 4 + 3 + 2 + 2), 2), 0) -> 4
A8: 2020/ICT/08 | B8: Ms. Devakumar P. | C8: C+ | D8: A- | E8: B | F8: B+ | G8: B | H8: =IFERROR( ROUND( ( (IF(C8="A+", 4, IF(C8="A", 4, IF(C8="A-", 3.7, IF(C8="B+", 3.3, IF(C8="B", 3, IF(C8="B-", 2.7, IF(C8="C+", 2.3, IF(C8="C", 2, IF(C8="C-", 1.7, IF(C8="D+", 1.3, IF(C8="D", 1, IF(C8="E", 0, 0)))))))))))) * 4) + (IF(D8="A+", 4, IF(D8="A", 4, IF(D8="A-", 3.7, IF(D8="B+", 3.3, IF(D8="B", 3, IF(D8="B-", 2.7, IF(D8="C+", 2.3, IF(D8="C", 2, IF(D8="C-", 1.7, IF(D8="D+", 1.3, IF(D8="D", 1, IF(D8="E", 0, 0)))))))))))) * 4) + (IF(E8="A+", 4, IF(E8="A", 4, IF(E8="A-", 3.7, IF(E8="B+", 3.3, IF(E8="B", 3, IF(E8="B-", 2.7, IF(E8="C+", 2.3, IF(E8="C", 2, IF(E8="C-", 1.7, IF(E8="D+", 1.3, IF(E8="D", 1, IF(E8="E", 0, 0)))))))))))) * 3) + (IF(F8="A+", 4, IF(F8="A", 4, IF(F8="A-", 3.7, IF(F8="B+", 3.3, IF(F8="B", 3, IF(F8="B-", 2.7, IF(F8="C+", 2.3, IF(F8="C", 2, IF(F8="C-", 1.7, IF(F8="D+", 1.3, IF(F8="D", 1, IF(F8="E", 0, 0)))))))))))) * 2) + (IF(G8="A+", 4, IF(G8="A", 4, IF(G8="A-", 3.7, IF(G8="B+", 3.3, IF(G8="B", 3, IF(G8="B-", 2.7, IF(G8="C+", 2.3, IF(G8="C", 2, IF(G8="C-", 1.7, IF(G8="D+", 1.3, IF(G8="D", 1, IF(G8="E", 0, 0)))))))))))) * 2) ) / (4 + 4 + 3 + 2 + 2), 2), 0) -> 3.04
A9: 2020/ICT/09 | B9: Ms. Senevirathne S.A. | C9: C | D9: B | E9: B+ | F9: C+ | G9: C- | H9: =IFERROR( ROUND( ( (IF(C9="A+", 4, IF(C9="A", 4, IF(C9="A-", 3.7, IF(C9="B+", 3.3, IF(C9="B", 3, IF(C9="B-", 2.7, IF(C9="C+", 2.3, IF(C9="C", 2, IF(C9="C-", 1.7, IF(C9="D+", 1.3, IF(C9="D", 1, IF(C9="E", 0, 0)))))))))))) * 4) + (IF(D9="A+", 4, IF(D9="A", 4, IF(D9="A-", 3.7, IF(D9="B+", 3.3, IF(D9="B", 3, IF(D9="B-", 2.7, IF(D9="C+", 2.3, IF(D9="C", 2, IF(D9="C-", 1.7, IF(D9="D+", 1.3, IF(D9="D", 1, IF(D9="E", 0, 0)))))))))))) * 4) + (IF(E9="A+", 4, IF(E9="A", 4, IF(E9="A-", 3.7, IF(E9="B+", 3.3, IF(E9="B", 3, IF(E9="B-", 2.7, IF(E9="C+", 2.3, IF(E9="C", 2, IF(E9="C-", 1.7, IF(E9="D+", 1.3, IF(E9="D", 1, IF(E9="E", 0, 0)))))))))))) * 3) + (IF(F9="A+", 4, IF(F9="A", 4, IF(F9="A-", 3.7, IF(F9="B+", 3.3, IF(F9="B", 3, IF(F9="B-", 2.7, IF(F9="C+", 2.3, IF(F9="C", 2, IF(F9="C-", 1.7, IF(F9="D+", 1.3, IF(F9="D", 1, IF(F9="E", 0, 0)))))))))))) * 2) + (IF(G9="A+", 4, IF(G9="A", 4, IF(G9="A-", 3.7, IF(G9="B+", 3.3, IF(G9="B", 3, IF(G9="B-", 2.7, IF(G9="C+", 2.3, IF(G9="C", 2, IF(G9="C-", 1.7, IF(G9="D+", 1.3, IF(G9="D", 1, IF(G9="E", 0, 0)))))))))))) * 2) ) / (4 + 4 + 3 + 2 + 2), 2), 0) -> 2.53
A10: 2020/ICT/10 | B10: Ms. Jegatheeswaran V. | C10: B+ | D10: A+ | E10: A+ | F10: A- | G10: A+ | H10: =IFERROR( ROUND( ( (IF(C10="A+", 4, IF(C10="A", 4, IF(C10="A-", 3.7, IF(C10="B+", 3.3, IF(C10="B", 3, IF(C10="B-", 2.7, IF(C10="C+", 2.3, IF(C10="C", 2, IF(C10="C-", 1.7, IF(C10="D+", 1.3, IF(C10="D", 1, IF(C10="E", 0, 0)))))))))))) * 4) + (IF(D10="A+", 4, IF(D10="A", 4, IF(D10="A-", 3.7, IF(D10="B+", 3.3, IF(D10="B", 3, IF(D10="B-", 2.7, IF(D10="C+", 2.3, IF(D10="C", 2, IF(D10="C-", 1.7, IF(D10="D+", 1.3, IF(D10="D", 1, IF(D10="E", 0, 0)))))))))))) * 4) + (IF(E10="A+", 4, IF(E10="A", 4, IF(E10="A-", 3.7, IF(E10="B+", 3.3, IF(E10="B", 3, IF(E10="B-", 2.7, IF(E10="C+", 2.3, IF(E10="C", 2, IF(E10="C-", 1.7, IF(E10="D+", 1.3, IF(E10="D", 1, IF(E10="E", 0, 0)))))))))))) * 3) + (IF(F10="A+", 4, IF(F10="A", 4, IF(F10="A-", 3.7, IF(F10="B+", 3.3, IF(F10="B", 3, IF(F10="B-", 2.7, IF(F10="C+", 2.3, IF(F10="C", 2, IF(F10="C-", 1.7, IF(F10="D+", 1.3, IF(F10="D", 1, IF(F10="E", 0, 0)))))))))))) * 2) + (IF(G10="A+", 4, IF(G10="A", 4, IF(G10="A-", 3.7, IF(G10="B+", 3.3, IF(G10="B", 3, IF(G10="B-", 2.7, IF(G10="C+", 2.3, IF(G10="C", 2, IF(G10="C-", 1.7, IF(G10="D+", 1.3, IF(G10="D", 1, IF(G10="E", 0, 0)))))))))))) * 2) ) / (4 + 4 + 3 + 2 + 2), 2), 0) -> 3.77
A11: 2020/ICT/12 | B11: Ms. Shahla A.A.F.S. | C11: A- | D11: A | E11: B+ | F11: B+ | G11: A | H11: =IFERROR( ROUND( ( (IF(C11="A+", 4, IF(C11="A", 4, IF(C11="A-", 3.7, IF(C11="B+", 3.3, IF(C11="B", 3, IF(C11="B-", 2.7, IF(C11="C+", 2.3, IF(C11="C", 2, IF(C11="C-", 1.7, IF(C11="D+", 1.3, IF(C11="D", 1, IF(C11="E", 0, 0)))))))))))) * 4) + (IF(D11="A+", 4, IF(D11="A", 4, IF(D11="A-", 3.7, IF(D11="B+", 3.3, IF(D11="B", 3, IF(D11="B-", 2.7, IF(D11="C+", 2.3, IF(D11="C", 2, IF(D11="C-", 1.7, IF(D11="D+", 1.3, IF(D11="D", 1, IF(D11="E", 0, 0)))))))))))) * 4) + (IF(E11="A+", 4, IF(E11="A", 4, IF(E11="A-", 3.7, IF(E11="B+", 3.3, IF(E11="B", 3, IF(E11="B-", 2.7, IF(E11="C+", 2.3, IF(E11="C", 2, IF(E11="C-", 1.7, IF(E11="D+", 1.3, IF(E11="D", 1, IF(E11="E", 0, 0)))))))))))) * 3) + (IF(F11="A+", 4, IF(F11="A", 4, IF(F11="A-", 3.7, IF(F11="B+", 3.3, IF(F11="B", 3, IF(F11="B-", 2.7, IF(F11="C+", 2.3, IF(F11="C", 2, IF(F11="C-", 1.7, IF(F11="D+", 1.3, IF(F11="D", 1, IF(F11="E", 0, 0)))))))))))) * 2) + (IF(G11="A+", 4, IF(G11="A", 4, IF(G11="A-", 3.7, IF(G11="B+", 3.3, IF(G11="B", 3, IF(G11="B-", 2.7, IF(G11="C+", 2.3, IF(G11="C", 2, IF(G11="C-", 1.7, IF(G11="D+", 1.3, IF(G11="D", 1, IF(G11="E", 0, 0)))))))))))) * 2) ) / (4 + 4 + 3 + 2 + 2), 2), 0) -> 3.69
A12: 2020/ICT/13 | B12: Ms. Basheery M.K.T. | C12: B | D12: A | E12: A | F12: A- | G12: A+ | H12: =IFERROR( ROUND( ( (IF(C12="A+", 4, IF(C12="A", 4, IF(C12="A-", 3.7, IF(C12="B+", 3.3, IF(C12="B", 3, IF(C12="B-", 2.7, IF(C12="C+", 2.3, IF(C12="C", 2, IF(C12="C-", 1.7, IF(C12="D+", 1.3, IF(C12="D", 1, IF(C12="E", 0, 0)))))))))))) * 4) + (IF(D12="A+", 4, IF(D12="A", 4, IF(D12="A-", 3.7, IF(D12="B+", 3.3, IF(D12="B", 3, IF(D12="B-", 2.7, IF(D12="C+", 2.3, IF(D12="C", 2, IF(D12="C-", 1.7, IF(D12="D+", 1.3, IF(D12="D", 1, IF(D12="E", 0, 0)))))))))))) * 4) + (IF(E12="A+", 4, IF(E12="A", 4, IF(E12="A-", 3.7, IF(E12="B+", 3.3, IF(E12="B", 3, IF(E12="B-", 2.7, IF(E12="C+", 2.3, IF(E12="C", 2, IF(E12="C-", 1.7, IF(E12="D+", 1.3, IF(E12="D", 1, IF(E12="E", 0, 0)))))))))))) * 3) + (IF(F12="A+", 4, IF(F12="A", 4, IF(F12="A-", 3.7, IF(F12="B+", 3.3, IF(F12="B", 3, IF(F12="B-", 2.7, IF(F12="C+", 2.3, IF(F12="C", 2, IF(F12="C-", 1.7, IF(F12="D+", 1.3, IF(F12="D", 1, IF(F12="E", 0, 0)))))))))))) * 2) + (IF(G12="A+", 4, IF(G12="A", 4, IF(G12="A-", 3.7, IF(G12="B+", 3.3, IF(G12="B", 3, IF(G12="B-", 2.7, IF(G12="C+", 2.3, IF(G12="C", 2, IF(G12="C-", 1.7, IF(G12="D+", 1.3, IF(G12="D", 1, IF(G12="E", 0, 0)))))))))))) * 2) ) / (4 + 4 + 3 + 2 + 2), 2), 0) -> 3.69
A13: 2020/ICT/14 | B13: Ms. Minha M.S.F. | C13: B+ | D13: A- | E13: A | F13: B+ | G13: A+ | H13: =IFERROR( ROUND( ( (IF(C13="A+", 4, IF(C13="A", 4, IF(C13="A-", 3.7, IF(C13="B+", 3.3, IF(C13="B", 3, IF(C13="B-", 2.7, IF(C13="C+", 2.3, IF(C13="C", 2, IF(C13="C-", 1.7, IF(C13="D+", 1.3, IF(C13="D", 1, IF(C13="E", 0, 0)))))))))))) * 4) + (IF(D13="A+", 4, IF(D13="A", 4, IF(D13="A-", 3.7, IF(D13="B+", 3.3, IF(D13="B", 3, IF(D13="B-", 2.7, IF(D13="C+", 2.3, IF(D13="C", 2, IF(D13="C-", 1.7, IF(D13="D+", 1.3, IF(D13="D", 1, IF(D13="E", 0, 0)))))))))))) * 4) + (IF(E13="A+", 4, IF(E13="A", 4, IF(E13="A-", 3.7, IF(E13="B+", 3.3, IF(E13="B", 3, IF(E13="B-", 2.7, IF(E13="C+", 2.3, IF(E13="C", 2, IF(E13="C-", 1.7, IF(E13="D+", 1.3, IF(E13="D", 1, IF(E13="E", 0, 0)))))))))))) * 3) + (IF(F13="A+", 4, IF(F13="A", 4, IF(F13="A-", 3.7, IF(F13="B+", 3.3, IF(F13="B", 3, IF(F13="B-", 2.7, IF(F13="C+", 2.3, IF(F13="C", 2, IF(F13="C-", 1.7, IF(F13="D+", 1.3, IF(F13="D", 1, IF(F13="E", 0, 0)))))))))))) * 2) + (IF(G13="A+", 4, IF(G13="A", 4, IF(G13="A-", 3.7, IF(G13="B+", 3.3, IF(G13="B", 3, IF(G13="B-", 2.7, IF(G13="C+", 2.3, IF(G13="C", 2, IF(G13="C-", 1.7, IF(G13="D+", 1.3, IF(G13="D", 1, IF(G13="E", 0, 0)))))))))))) * 2) ) / (4 + 4 + 3 + 2 + 2), 2), 0) -> 3.64
... A108: 2020/ICT/120 | B108: Ms.Thavarajah H | C108: C | D108: B- | E108: B- | F108: B- | G108: C- | H108: =IFERROR( ROUND( ( (IF(C108="A+", 4, IF(C108="A", 4, IF(C108="A-", 3.7, IF(C108="B+", 3.3, IF(C108="B", 3, IF(C108="B-", 2.7, IF(C108="C+", 2.3, IF(C108="C", 2, IF(C108="C-", 1.7, IF(C108="D+", 1.3, IF(C108="D", 1, IF(C108="E", 0, 0)))))))))))) * 4) + (IF(D108="A+", 4, IF(D108="A", 4, IF(D108="A-", 3.7, IF(D108="B+", 3.3, IF(D108="B", 3, IF(D108="B-", 2.7, IF(D108="C+", 2.3, IF(D108="C", 2, IF(D108="C-", 1.7, IF(D108="D+", 1.3, IF(D108="D", 1, IF(D108="E", 0, 0)))))))))))) * 4) + (IF(E108="A+", 4, IF(E108="A", 4, IF(E108="A-", 3.7, IF(E108="B+", 3.3, IF(E108="B", 3, IF(E108="B-", 2.7, IF(E108="C+", 2.3, IF(E108="C", 2, IF(E108="C-", 1.7, IF(E108="D+", 1.3, IF(E108="D", 1, IF(E108="E", 0, 0)))))))))))) * 3) + (IF(F108="A+", 4, IF(F108="A", 4, IF(F108="A-", 3.7, IF(F108="B+", 3.3, IF(F108="B", 3, IF(F108="B-", 2.7, IF(F108="C+", 2.3, IF(F108="C", 2, IF(F108="C-", 1.7, IF(F108="D+", 1.3, IF(F108="D", 1, IF(F108="E", 0, 0)))))))))))) * 2) + (IF(G108="A+", 4, IF(G108="A", 4, IF(G108="A-", 3.7, IF(G108="B+", 3.3, IF(G108="B", 3, IF(G108="B-", 2.7, IF(G108="C+", 2.3, IF(G108="C", 2, IF(G108="C-", 1.7, IF(G108="D+", 1.3, IF(G108="D", 1, IF(G108="E", 0, 0)))))))))))) * 2) ) / (4 + 4 + 3 + 2 + 2), 2), 0) -> 2.38

Sheet 1.2
A1: Reg.No | B1: Name | C1: IT1214 | D1: IT1223 | E1: IT1232 | F1: IT1242 | G1: IT1252 | H1: IT1262 | I1: GPA
A2: 2020/ICT/01 | B2: Ms. Udisha W.H.I | C2: A+ | D2: A- | E2: A+ | F2: A- | G2: B | H2: C | I2: =#VALUE! -> #VALUE!
A3: 2020/ICT/02 | B3: Mr. Imran B.M. | C3: C | D3: C | E3: D | F3: C | G3: E | H3: D | I3: =#VALUE! -> #VALUE!
A4: 2020/ICT/03 | B4: Ms. Shanmugarajah D. | C4: A | D4: B | E4: B | F4: C- | G4: C+ | H4: C+ | I4: =#VALUE! -> #VALUE!
A5: 2020/ICT/05 | B5: Mr. Muniweera K.G.U.K. | C5: A+ | D5: A | E5: C+ | F5: B+ | G5: B+ | H5: D | I5: =#VALUE! -> #VALUE!
A6: 2020/ICT/06 | B6: Ms. Lourdes Jellorine | C6: A+ | D6: A+ | E6: A | F6: B | G6: B+ | H6: A+ | I6: =#VALUE! -> #VALUE!
A7: 2020/ICT/07 | B7: Mr. Nalawansa U.K | C7: A+ | D7: A+ | E7: A | F7: B- | G7: A | H7: C+ | I7: =#VALUE! -> #VALUE!
A8: 2020/ICT/08 | B8: Ms. Devakumar P. | C8: B+ | D8: C+ | E8: B | F8: C- | G8: C+ | H8: C- | I8: =#VALUE! -> #VALUE!
A9: 2020/ICT/09 | B9: Ms. Senevirathne S.A. | C9: B+ | D9: B+ | E9: B+ | F9: C | G9: B | H9: C- | I9: =#VALUE! -> #VALUE!
A10: 2020/ICT/10 | B10: Ms. Jegatheeswaran V. | C10: A- | D10: A+ | E10: A | F10: B+ | G10: C+ | H10: C- | I10: =#VALUE! -> #VALUE!
A11: 2020/ICT/12 | B11: Ms. Shahla A.A.F.S. | C11: A | D11: A | E11: B | F11: B- | G11: B | H11: C+ | I11: =#VALUE! -> #VALUE!
A12: 2020/ICT/13 | B12: Ms. Basheery M.K.T. | C12: A+ | D12: A- | E12: B | F12: C | G12: B- | H12: C- | I12: =#VALUE! -> #VALUE!
A13: 2020/ICT/14 | B13: Ms. Minha M.S.F. | C13: A+ | D13: A | E13: B+ | F13: C+ | G13: B | H13: C- | I13: =#VALUE! -> #VALUE!
... A108: 2020/ICT/120 | B108: Ms.Thavarajah H | C108: B- | D108: B | E108: C | F108: C | G108: C | H108: B+ | I108: =#VALUE! -> #VALUE!

Sheet 2.1
A1: Reg.No | B1: Name | C1: IT2114 | D1: IT2133 | E1: IT2153 | F1: IT2143 | G1: IT2122 | H1: GPA
A2: 2020/ICT/01 | B2: Ms. Udisha W.H.I | C2: A | D2: B+ | E2: A- | F2: A | G2: B | H2: =IFERROR( ROUND( ( (IF(C2="A+", 4, IF(C2="A", 4, IF(C2="A-", 3.7, IF(C2="B+", 3.3, IF(C2="B", 3, IF(C2="B-", 2.7, IF(C2="C+", 2.3, IF(C2="C", 2, IF(C2="C-", 1.7, IF(C2="D+", 1.3, IF(C2="D", 1, IF(C2="E", 0, 0))))))))))))) * 4 + (IF(D2="A+", 4, IF(D2="A", 4, IF(D2="A-", 3.7, IF(D2="B+", 3.3, IF(D2="B", 3, IF(D2="B-", 2.7, IF(D2="C+", 2.3, IF(D2="C", 2, IF(D2="C-", 1.7, IF(D2="D+", 1.3, IF(D2="D", 1, IF(D2="E", 0, 0))))))))))))) * 3 + (IF(E2="A+", 4, IF(E2="A", 4, IF(E2="A-", 3.7, IF(E2="B+", 3.3, IF(E2="B", 3, IF(E2="B-", 2.7, IF(E2="C+", 2.3, IF(E2="C", 2, IF(E2="C-", 1.7, IF(E2="D+", 1.3, IF(E2="D", 1, IF(E2="E", 0, 0))))))))))))) * 3 + (IF(F2="A+", 4, IF(F2="A", 4, IF(F2="A-", 3.7, IF(F2="B+", 3.3, IF(F2="B", 3, IF(F2="B-", 2.7, IF(F2="C+", 2.3, IF(F2="C", 2, IF(F2="C-", 1.7, IF(F2="D+", 1.3, IF(F2="D", 1, IF(F2="E", 0, 0))))))))))))) * 3 + (IF(G2="A+", 4, IF(G2="A", 4, IF(G2="A-", 3.7, IF(G2="B+", 3.3, IF(G2="B", 3, IF(G2="B-", 2.7, IF(G2="C+", 2.3, IF(G2="C", 2, IF(G2="C-", 1.7, IF(G2="D+", 1.3, IF(G2="D", 1, IF(G2="E", 0, 0))))))))))))) * 2 ) / (4 + 3 + 3 + 3 + 2), 2), 0) -> 3.67
A3: 2020/ICT/02 | B3: Mr. Imran B.M. | C3: absent | D3: C- | E3: absent | F3: C | G3: C | H3: =IFERROR( ROUND( ( (IF(C3="A+", 4, IF(C3="A", 4, IF(C3="A-", 3.7, IF(C3="B+", 3.3, IF(C3="B", 3, IF(C3="B-", 2.7, IF(C3="C+", 2.3, IF(C3="C", 2, IF(C3="C-", 1.7, IF(C3="D+", 1.3, IF(C3="D", 1, IF(C3="E", 0, 0))))))))))))) * 4 + (IF(D3="A+", 4, IF(D3="A", 4, IF(D3="A-", 3.7, IF(D3="B+", 3.3, IF(D3="B", 3, IF(D3="B-", 2.7, IF(D3="C+", 2.3, IF(D3="C", 2, IF(D3="C-", 1.7, IF(D3="D+", 1.3, IF(D3="D", 1, IF(D3="E", 0, 0))))))))))))) * 3 + (IF(E3="A+", 4, IF(E3="A", 4, IF(E3="A-", 3.7, IF(E3="B+", 3.3, IF(E3="B", 3, IF(E3="B-", 2.7, IF(E3="C+", 2.3, IF(E3="C", 2, IF(E3="C-", 1.7, IF(E3="D+", 1.3, IF(E3="D", 1, IF(E3="E", 0, 0))))))))))))) * 3 + (IF(F3="A+", 4, IF(F3="A", 4, IF(F3="A-", 3.7, IF(F3="B+", 3.3, IF(F3="B", 3, IF(F3="B-", 2.7, IF(F3="C+", 2.3, IF(F3="C", 2, IF(F3="C-", 1.7, IF(F3="D+", 1.3, IF(F3="D", 1, IF(F3="E", 0, 0))))))))))))) * 3 + (IF(G3="A+", 4, IF(G3="A", 4, IF(G3="A-", 3.7, IF(G3="B+", 3.3, IF(G3="B", 3, IF(G3="B-", 2.7, IF(G3="C+", 2.3, IF(G3="C", 2, IF(G3="C-", 1.7, IF(G3="D+", 1.3, IF(G3="D", 1, IF(G3="E", 0, 0))))))))))))) * 2) / (4 + 3 + 3 + 3 + 2), 2), 0) -> 1.01
A4: 2020/ICT/03 | B4: Ms. Shanmugarajah D. | C4: A- | D4: B | E4: C+ | F4: B | G4: B- | H4: =IFERROR( ROUND( ( (IF(C4="A+", 4, IF(C4="A", 4, IF(C4="A-", 3.7, IF(C4="B+", 3.3, IF(C4="B", 3, IF(C4="B-", 2.7, IF(C4="C+", 2.3, IF(C4="C", 2, IF(C4="C-", 1.7, IF(C4="D+", 1.3, IF(C4="D", 1, IF(C4="E", 0, 0))))))))))))) * 4 + (IF(D4="A+", 4, IF(D4="A", 4, IF(D4="A-", 3.7, IF(D4="B+", 3.3, IF(D4="B", 3, IF(D4="B-", 2.7, IF(D4="C+", 2.3, IF(D4="C", 2, IF(D4="C-", 1.7, IF(D4="D+", 1.3, IF(D4="D", 1, IF(D4="E", 0, 0))))))))))))) * 3 + (IF(E4="A+", 4, IF(E4="A", 4, IF(E4="A-", 3.7, IF(E4="B+", 3.3, IF(E4="B", 3, IF(E4="B-", 2.7, IF(E4="C+", 2.3, IF(E4="C", 2, IF(E4="C-", 1.7, IF(E4="D+", 1.3, IF(E4="D", 1, IF(E4="E", 0, 0))))))))))))) * 3 + (IF(F4="A+", 4, IF(F4="A", 4, IF(F4="A-", 3.7, IF(F4="B+", 3.3, IF(F4="B", 3, IF(F4="B-", 2.7, IF(F4="C+", 2.3, IF(F4="C", 2, IF(F4="C-", 1.7, IF(F4="D+", 1.3, IF(F4="D", 1, IF(F4="E", 0, 0))))))))))))) * 3 + (IF(G4="A+", 4, IF(G4="A", 4, IF(G4="A-", 3.7, IF(G4="B+", 3.3, IF(G4="B", 3, IF(G4="B-", 2.7, IF(G4="C+", 2.3, IF(G4="C", 2, IF(G4="C-", 1.7, IF(G4="D+", 1.3, IF(G4="D", 1, IF(G4="E", 0, 0))))))))))))) * 2) / (4 + 3 + 3 + 3 + 2), 2), 0) -> 3.01
A5: 2020/ICT/05 | B5: Mr. Muniweera K.G.U.K. | C5: A | D5: B+ | E5: E | F5: B | G5: B- | H5: =IFERROR( ROUND( ( (IF(C5="A+", 4, IF(C5="A", 4, IF(C5="A-", 3.7, IF(C5="B+", 3.3, IF(C5="B", 3, IF(C5="B-", 2.7, IF(C5="C+", 2.3, IF(C5="C", 2, IF(C5="C-", 1.7, IF(C5="D+", 1.3, IF(C5="D", 1, IF(C5="E", 0, 0))))))))))))) * 4 + (IF(D5="A+", 4, IF(D5="A", 4, IF(D5="A-", 3.7, IF(D5="B+", 3.3, IF(D5="B", 3, IF(D5="B-", 2.7, IF(D5="C+", 2.3, IF(D5="C", 2, IF(D5="C-", 1.7, IF(D5="D+", 1.3, IF(D5="D", 1, IF(D5="E", 0, 0))))))))))))) * 3 + (IF(E5="A+", 4, IF(E5="A", 4, IF(E5="A-", 3.7, IF(E5="B+", 3.3, IF(E5="B", 3, IF(E5="B-", 2.7, IF(E5="C+", 2.3, IF(E5="C", 2, IF(E5="C-", 1.7, IF(E5="D+", 1.3, IF(E5="D", 1, IF(E5="E", 0, 0))))))))))))) * 3 + (IF(F5="A+", 4, IF(F5="A", 4, IF(F5="A-", 3.7, IF(F5="B+", 3.3, IF(F5="B", 3, IF(F5="B-", 2.7, IF(F5="C+", 2.3, IF(F5="C", 2, IF(F5="C-", 1.7, IF(F5="D+", 1.3, IF(F5="D", 1, IF(F5="E", 0, 0))))))))))))) * 3 + (IF(G5="A+", 4, IF(G5="A", 4, IF(G5="A-", 3.7, IF(G5="B+", 3.3, IF(G5="B", 3, IF(G5="B-", 2.7, IF(G5="C+", 2.3, IF(G5="C", 2, IF(G5="C-", 1.7, IF(G5="D+", 1.3, IF(G5="D", 1, IF(G5="E", 0, 0))))))))))))) * 2) / (4 + 3 + 3 + 3 + 2), 2), 0) -> 2.69
A6: 2020/ICT/06 | B6: Ms. Lourdes Jellorine | C6: A+ | D6: A | E6: A+ | F6: A | G6: B | H6: =IFERROR( ROUND( ( (IF(C6="A+", 4, IF(C6="A", 4, IF(C6="A-", 3.7, IF(C6="B+", 3.3, IF(C6="B", 3, IF(C6="B-", 2.7, IF(C6="C+", 2.3, IF(C6="C", 2, IF(C6="C-", 1.7, IF(C6="D+", 1.3, IF(C6="D", 1, IF(C6="E", 0, 0))))))))))))) * 4 + (IF(D6="A+", 4, IF(D6="A", 4, IF(D6="A-", 3.7, IF(D6="B+", 3.3, IF(D6="B", 3, IF(D6="B-", 2.7, IF(D6="C+", 2.3, IF(D6="C", 2, IF(D6="C-", 1.7, IF(D6="D+", 1.3, IF(D6="D", 1, IF(D6="E", 0, 0))))))))))))) * 3 + (IF(E6="A+", 4, IF(E6="A", 4, IF(E6="A-", 3.7, IF(E6="B+", 3.3, IF(E6="B", 3, IF(E6="B-", 2.7, IF(E6="C+", 2.3, IF(E6="C", 2, IF(E6="C-", 1.7, IF(E6="D+", 1.3, IF(E6="D", 1, IF(E6="E", 0, 0))))))))))))) * 3 + (IF(F6="A+", 4, IF(F6="A", 4, IF(F6="A-", 3.7, IF(F6="B+", 3.3, IF(F6="B", 3, IF(F6="B-", 2.7, IF(F6="C+", 2.3, IF(F6="C", 2, IF(F6="C-", 1.7, IF(F6="D+", 1.3, IF(F6="D", 1, IF(F6="E", 0, 0))))))))))))) * 3 + (IF(G6="A+", 4, IF(G6="A", 4, IF(G6="A-", 3.7, IF(G6="B+", 3.3, IF(G6="B", 3, IF(G6="B-", 2.7, IF(G6="C+", 2.3, IF(G6="C", 2, IF(G6="C-", 1.7, IF(G6="D+", 1.3, IF(G6="D", 1, IF(G6="E", 0, 0))))))))))))) * 2) / (4 + 3 + 3 + 3 + 2), 2), 0) -> 3.87
A7: 2020/ICT/07 | B7: Mr. Nalawansa U.K | C7: A+ | D7: A- | E7: A- | F7: A | G7: B | H7: =IFERROR( ROUND( ( (IF(C7="A+", 4, IF(C7="A", 4, IF(C7="A-", 3.7, IF(C7="B+", 3.3, IF(C7="B", 3, IF(C7="B-", 2.7, IF(C7="C+", 2.3, IF(C7="C", 2, IF(C7="C-", 1.7, IF(C7="D+", 1.3, IF(C7="D", 1, IF(C7="E", 0, 0))))))))))))) * 4 + (IF(D7="A+", 4, IF(D7="A", 4, IF(D7="A-", 3.7, IF(D7="B+", 3.3, IF(D7="B", 3, IF(D7="B-", 2.7, IF(D7="C+", 2.3, IF(D7="C", 2, IF(D7="C-", 1.7, IF(D7="D+", 1.3, IF(D7="D", 1, IF(D7="E", 0, 0))))))))))))) * 3 + (IF(E7="A+", 4, IF(E7="A", 4, IF(E7="A-", 3.7, IF(E7="B+", 3.3, IF(E7="B", 3, IF(E7="B-", 2.7, IF(E7="C+", 2.3, IF(E7="C", 2, IF(E7="C-", 1.7, IF(E7="D+", 1.3, IF(E7="D", 1, IF(E7="E", 0, 0))))))))))))) * 3 + (IF(F7="A+", 4, IF(F7="A", 4, IF(F7="A-", 3.7, IF(F7="B+", 3.3, IF(F7="B", 3, IF(F7="B-", 2.7, IF(F7="C+", 2.3, IF(F7="C", 2, IF(F7="C-", 1.7, IF(F7="D+", 1.3, IF(F7="D", 1, IF(F7="E", 0, 0))))))))))))) * 3 + (IF(G7="A+", 4, IF(G7="A", 4, IF(G7="A-", 3.7, IF(G7="B+", 3.3, IF(G7="B", 3, IF(G7="B-", 2.7, IF(G7="C+", 2.3, IF(G7="C", 2, IF(G7="C-", 1.7, IF(G7="D+", 1.3, IF(G7="D", 1, IF(G7="E", 0, 0))))))))))))) * 2) / (4 + 3 + 3 + 3 + 2), 2), 0) -> 3.75
A8: 2020/ICT/08 | B8: Ms. Devakumar P. | C8: B- | D8: B | E8: C+ | F8: B- | G8: B- | H8: =IFERROR( ROUND( ( (IF(C8="A+", 4, IF(C8="A", 4, IF(C8="A-", 3.7, IF(C8="B+", 3.3, IF(C8="B", 3, IF(C8="B-", 2.7, IF(C8="C+", 2.3, IF(C8="C", 2, IF(C8="C-", 1.7, IF(C8="D+", 1.3, IF(C8="D", 1, IF(C8="E", 0, 0))))))))))))) * 4 + (IF(D8="A+", 4, IF(D8="A", 4, IF(D8="A-", 3.7, IF(D8="B+", 3.3, IF(D8="B", 3, IF(D8="B-", 2.7, IF(D8="C+", 2.3, IF(D8="C", 2, IF(D8="C-", 1.7, IF(D8="D+", 1.3, IF(D8="D", 1, IF(D8="E", 0, 0))))))))))))) * 3 + (IF(E8="A+", 4, IF(E8="A", 4, IF(E8="A-", 3.7, IF(E8="B+", 3.3, IF(E8="B", 3, IF(E8="B-", 2.7, IF(E8="C+", 2.3, IF(E8="C", 2, IF(E8="C-", 1.7, IF(E8="D+", 1.3, IF(E8="D", 1, IF(E8="E", 0, 0))))))))))))) * 3 + (IF(F8="A+", 4, IF(F8="A", 4, IF(F8="A-", 3.7, IF(F8="B+", 3.3, IF(F8="B", 3, IF(F8="B-", 2.7, IF(F8="C+", 2.3, IF(F8="C", 2, IF(F8="C-", 1.7, IF(F8="D+", 1.3, IF(F8="D", 1, IF(F8="E", 0, 0))))))))))))) * 3 + (IF(G8="A+", 4, IF(G8="A", 4, IF(G8="A-", 3.7, IF(G8="B+", 3.3, IF(G8="B", 3, IF(G8="B-", 2.7, IF(G8="C+", 2.3, IF(G8="C", 2, IF(G8="C-", 1.7, IF(G8="D+", 1.3, IF(G8="D", 1, IF(G8="E", 0, 0))))))))))))) * 2) / (4 + 3 + 3 + 3 + 2), 2), 0) -> 2.68
A9: 2020/ICT/09 | B9: Ms. Senevirathne S.A. | C9: B- | D9: C+ | E9: C | F9: C+ | G9: C+ | H9: =IFERROR( ROUND( ( (IF(C9="A+", 4, IF(C9="A", 4, IF(C9="A-", 3.7, IF(C9="B+", 3.3, IF(C9="B", 3, IF(C9="B-", 2.7, IF(C9="C+", 2.3, IF(C9="C", 2, IF(C9="C-", 1.7, IF(C9="D+", 1.3, IF(C9="D", 1, IF(C9="E", 0, 0))))))))))))) * 4 + (IF(D9="A+", 4, IF(D9="A", 4, IF(D9="A-", 3.7, IF(D9="B+", 3.3, IF(D9="B", 3, IF(D9="B-", 2.7, IF(D9="C+", 2.3, IF(D9="C", 2, IF(D9="C-", 1.7, IF(D9="D+", 1.3, IF(D9="D", 1, IF(D9="E", 0, 0))))))))))))) * 3 + (IF(E9="A+", 4, IF(E9="A", 4, IF(E9="A-", 3.7, IF(E9="B+", 3.3, IF(E9="B", 3, IF(E9="B-", 2.7, IF(E9="C+", 2.3, IF(E9="C", 2, IF(E9="C-", 1.7, IF(E9="D+", 1.3, IF(E9="D", 1, IF(E9="E", 0, 0))))))))))))) * 3 + (IF(F9="A+", 4, IF(F9="A", 4, IF(F9="A-", 3.7, IF(F9="B+", 3.3, IF(F9="B", 3, IF(F9="B-", 2.7, IF(F9="C+", 2.3, IF(F9="C", 2, IF(F9="C-", 1.7, IF(F9="D+", 1.3, IF(F9="D", 1, IF(F9="E", 0, 0))))))))))))) * 3 + (IF(G9="A+", 4, IF(G9="A", 4, IF(G9="A-", 3.7, IF(G9="B+", 3.3, IF(G9="B", 3, IF(G9="B-", 2.7, IF(G9="C+", 2.3, IF(G9="C", 2, IF(G9="C-", 1.7, IF(G9="D+", 1.3, IF(G9="D", 1, IF(G9="E", 0, 0))))))))))))) * 2) / (4 + 3 + 3 + 3 + 2), 2), 0) -> 2.35
A10: 2020/ICT/10 | B10: Ms. Jegatheeswaran V. | C10: B | D10: B+ | E10: B- | F10: B- | G10: B | H10: =IFERROR( ROUND( ( (IF(C10="A+", 4, IF(C10="A", 4, IF(C10="A-", 3.7, IF(C10="B+", 3.3, IF(C10="B", 3, IF(C10="B-", 2.7, IF(C10="C+", 2.3, IF(C10="C", 2, IF(C10="C-", 1.7, IF(C10="D+", 1.3, IF(C10="D", 1, IF(C10="E", 0, 0))))))))))))) * 4 + (IF(D10="A+", 4, IF(D10="A", 4, IF(D10="A-", 3.7, IF(D10="B+", 3.3, IF(D10="B", 3, IF(D10="B-", 2.7, IF(D10="C+", 2.3, IF(D10="C", 2, IF(D10="C-", 1.7, IF(D10="D+", 1.3, IF(D10="D", 1, IF(D10="E", 0, 0))))))))))))) * 3 + (IF(E10="A+", 4, IF(E10="A", 4, IF(E10="A-", 3.7, IF(E10="B+", 3.3, IF(E10="B", 3, IF(E10="B-", 2.7, IF(E10="C+", 2.3, IF(E10="C", 2, IF(E10="C-", 1.7, IF(E10="D+", 1.3, IF(E10="D", 1, IF(E10="E", 0, 0))))))))))))) * 3 + (IF(F10="A+", 4, IF(F10="A", 4, IF(F10="A-", 3.7, IF(F10="B+", 3.3, IF(F10="B", 3, IF(F10="B-", 2.7, IF(F10="C+", 2.3, IF(F10="C", 2, IF(F10="C-", 1.7, IF(F10="D+", 1.3, IF(F10="D", 1, IF(F10="E", 0, 0))))))))))))) * 3 + (IF(G10="A+", 4, IF(G10="A", 4, IF(G10="A-", 3.7, IF(G10="B+", 3.3, IF(G10="B", 3, IF(G10="B-", 2.7, IF(G10="C+", 2.3, IF(G10="C", 2, IF(G10="C-", 1.7, IF(G10="D+", 1.3, IF(G10="D", 1, IF(G10="E", 0, 0))))))))))))) * 2) / (4 + 3 + 3 + 3 + 2), 2), 0) -> 2.94
A11: 2020/ICT/12 | B11: Ms. Shahla A.A.F.S. | C11: A- | D11: A- | E11: B+ | F11: B | G11: C | H11: =IFERROR( ROUND( ( (IF(C11="A+", 4, IF(C11="A", 4, IF(C11="A-", 3.7, IF(C11="B+", 3.3, IF(C11="B", 3, IF(C11="B-", 2.7, IF(C11="C+", 2.3, IF(C11="C", 2, IF(C11="C-", 1.7, IF(C11="D+", 1.3, IF(C11="D", 1, IF(C11="E", 0, 0))))))))))))) * 4 + (IF(D11="A+", 4, IF(D11="A", 4, IF(D11="A-", 3.7, IF(D11="B+", 3.3, IF(D11="B", 3, IF(D11="B-", 2.7, IF(D11="C+", 2.3, IF(D11="C", 2, IF(D11="C-", 1.7, IF(D11="D+", 1.3, IF(D11="D", 1, IF(D11="E", 0, 0))))))))))))) * 3 + (IF(E11="A+", 4, IF(E11="A", 4, IF(E11="A-", 3.7, IF(E11="B+", 3.3, IF(E11="B", 3, IF(E11="B-", 2.7, IF(E11="C+", 2.3, IF(E11="C", 2, IF(E11="C-", 1.7, IF(E11="D+", 1.3, IF(E11="D", 1, IF(E11="E", 0, 0))))))))))))) * 3 + (IF(F11="A+", 4, IF(F11="A", 4, IF(F11="A-", 3.7, IF(F11="B+", 3.3, IF(F11="B", 3, IF(F11="B-", 2.7, IF(F11="C+", 2.3, IF(F11="C", 2, IF(F11="C-", 1.7, IF(F11="D+", 1.3, IF(F11="D", 1, IF(F11="E", 0, 0))))))))))))) * 3 + (IF(G11="A+", 4, IF(G11="A", 4, IF(G11="A-", 3.7, IF(G11="B+", 3.3, IF(G11="B", 3, IF(G11="B-", 2.7, IF(G11="C+", 2.3, IF(G11="C", 2, IF(G11="C-", 1.7, IF(G11="D+", 1.3, IF(G11="D", 1, IF(G11="E", 0, 0))))))))))))) * 2) / (4 + 3 + 3 + 3 + 2), 2), 0) -> 3.25
A12: 2020/ICT/13 | B12: Ms. Basheery M.K.T. | C12: C | D12: B | E12: C+ | F12: C+ | G12: C | H12: =IFERROR( ROUND( ( (IF(C12="A+", 4, IF(C12="A", 4, IF(C12="A-", 3.7, IF(C12="B+", 3.3, IF(C12="B", 3, IF(C12="B-", 2.7, IF(C12="C+", 2.3, IF(C12="C", 2, IF(C12="C-", 1.7, IF(C12="D+", 1.3, IF(C12="D", 1, IF(C12="E", 0, 0))))))))))))) * 4 + (IF(D12="A+", 4, IF(D12="A", 4, IF(D12="A-", 3.7, IF(D12="B+", 3.3, IF(D12="B", 3, IF(D12="B-", 2.7, IF(D12="C+", 2.3, IF(D12="C", 2, IF(D12="C-", 1.7, IF(D12="D+", 1.3, IF(D12="D", 1, IF(D12="E", 0, 0))))))))))))) * 3 + (IF(E12="A+", 4, IF(E12="A", 4, IF(E12="A-", 3.7, IF(E12="B+", 3.3, IF(E12="B", 3, IF(E12="B-", 2.7, IF(E12="C+", 2.3, IF(E12="C", 2, IF(E12="C-", 1.7, IF(E12="D+", 1.3, IF(E12="D", 1, IF(E12="E", 0, 0))))))))))))) * 3 + (IF(F12="A+", 4, IF(F12="A", 4, IF(F12="A-", 3.7, IF(F12="B+", 3.3, IF(F12="B", 3, IF(F12="B-", 2.7, IF(F12="C+", 2.3, IF(F12="C", 2, IF(F12="C-", 1.7, IF(F12="D+", 1.3, IF(F12="D", 1, IF(F12="E", 0, 0))))))))))))) * 3 + (IF(G12="A+", 4, IF(G12="A", 4, IF(G12="A-", 3.7, IF(G12="B+", 3.3, IF(G12="B", 3, IF(G12="B-", 2.7, IF(G12="C+", 2.3, IF(G12="C", 2, IF(G12="C-", 1.7, IF(G12="D+", 1.3, IF(G12="D", 1, IF(G12="E", 0, 0))))))))))))) * 2) / (4 + 3 + 3 + 3 + 2), 2), 0) -> 2.32
A13: 2020/ICT/14 | B13: Ms. Minha M.S.F. | C13: A | D13: A- | E13: B+ | F13: B+ | G13: C+ | H13: =IFERROR( ROUND( ( (IF(C13="A+", 4, IF(C13="A", 4, IF(C13="A-", 3.7, IF(C13="B+", 3.3, IF(C13="B", 3, IF(C13="B-", 2.7, IF(C13="C+", 2.3, IF(C13="C", 2, IF(C13="C-", 1.7, IF(C13="D+", 1.3, IF(C13="D", 1, IF(C13="E", 0, 0))))))))))))) * 4 + (IF(D13="A+", 4, IF(D13="A", 4, IF(D13="A-", 3.7, IF(D13="B+", 3.3, IF(D13="B", 3, IF(D13="B-", 2.7, IF(D13="C+", 2.3, IF(D13="C", 2, IF(D13="C-", 1.7, IF(D13="D+", 1.3, IF(D13="D", 1, IF(D13="E", 0, 0))))))))))))) * 3 + (IF(E13="A+", 4, IF(E13="A", 4, IF(E13="A-", 3.7, IF(E13="B+", 3.3, IF(E13="B", 3, IF(E13="B-", 2.7, IF(E13="C+", 2.3, IF(E13="C", 2, IF(E13="C-", 1.7, IF(E13="D+", 1.3, IF(E13="D", 1, IF(E13="E", 0, 0))))))))))))) * 3 + (IF(F13="A+", 4, IF(F13="A", 4, IF(F13="A-", 3.7, IF(F13="B+", 3.3, IF(F13="B", 3, IF(F13="B-", 2.7, IF(F13="C+", 2.3, IF(F13="C", 2, IF(F13="C-", 1.7, IF(F13="D+", 1.3, IF(F13="D", 1, IF(F13="E", 0, 0))))))))))))) * 3 + (IF(G13="A+", 4, IF(G13="A", 4, IF(G13="A-", 3.7, IF(G13="B+", 3.3, IF(G13="B", 3, IF(G13="B-", 2.7, IF(G13="C+", 2.3, IF(G13="C", 2, IF(G13="C-", 1.7, IF(G13="D+", 1.3, IF(G13="D", 1, IF(G13="E", 0, 0))))))))))))) * 2) / (4 + 3 + 3 + 3 + 2), 2), 0) -> 3.43
A14: 2020/ICT/15 | B14: Mr. Krishan S. | C14: B+ | D14: B- | E14: C+ | F14: B+ | G14: B+ | H14: =IFERROR( ROUND( ( (IF(C14="A+", 4, IF(C14="A", 4, IF(C14="A-", 3.7, IF(C14="B+", 3.3, IF(C14="B", 3, IF(C14="B-", 2.7, IF(C14="C+", 2.3, IF(C14="C", 2, IF(C14="C-", 1.7, IF(C14="D+", 1.3, IF(C14="D", 1, IF(C14="E", 0, 0))))))))))))) * 4 + (IF(D14="A+", 4, IF(D14="A", 4, IF(D14="A-", 3.7, IF(D14="B+", 3.3, IF(D14="B", 3, IF(D14="B-", 2.7, IF(D14="C+", 2.3, IF(D14="C", 2, IF(D14="C-", 1.7, IF(D14="D+", 1.3, IF(D14="D", 1, IF(D14="E", 0, 0))))))))))))) * 3 + (IF(E14="A+", 4, IF(E14="A", 4, IF(E14="A-", 3.7, IF(E14="B+", 3.3, IF(E14="B", 3, IF(E14="B-", 2.7, IF(E14="C+", 2.3, IF(E14="C", 2, IF(E14="C-", 1.7, IF(E14="D+", 1.3, IF(E14="D", 1, IF(E14="E", 0, 0))))))))))))) * 3 + (IF(F14="A+", 4, IF(F14="A", 4, IF(F14="A-", 3.7, IF(F14="B+", 3.3, IF(F14="B", 3, IF(F14="B-", 2.7, IF(F14="C+", 2.3, IF(F14="C", 2, IF(F14="C-", 1.7, IF(F14="D+", 1.3, IF(F14="D", 1, IF(F14="E", 0, 0))))))))))))) * 3 + (IF(G14="A+", 4, IF(G14="A", 4, IF(G14="A-", 3.7, IF(G14="B+", 3.3, IF(G14="B", 3, IF(G14="B-", 2.7, IF(G14="C+", 2.3, IF(G14="C", 2, IF(G14="C-", 1.7, IF(G14="D+", 1.3, IF(G14="D", 1, IF(G14="E", 0, 0))))))))))))) * 2) / (4 + 3 + 3 + 3 + 2), 2), 0) -> 2.98
... A74: 2020/ICT/85 | B74: Ms. Gunarathna P.M.D.P.R.P. | C74: B+ | D74: A- | E74: B- | F74: B- | G74: B- | H74: =IFERROR( ROUND( ( (IF(C74="A+", 4, IF(C74="A", 4, IF(C74="A-", 3.7, IF(C74="B+", 3.3, IF(C74="B", 3, IF(C74="B-", 2.7, IF(C74="C+", 2.3, IF(C74="C", 2, IF(C74="C-", 1.7, IF(C74="D+", 1.3, IF(C74="D", 1, IF(C74="E", 0, 0))))))))))))) * 4 + (IF(D74="A+", 4, IF(D74="A", 4, IF(D74="A-", 3.7, IF(D74="B+", 3.3, IF(D74="B", 3, IF(D74="B-", 2.7, IF(D74="C+", 2.3, IF(D74="C", 2, IF(D74="C-", 1.7, IF(D74="D+", 1.3, IF(D74="D", 1, IF(D74="E", 0, 0))))))))))))) * 3 + (IF(E74="A+", 4, IF(E74="A", 4, IF(E74="A-", 3.7, IF(E74="B+", 3.3, IF(E74="B", 3, IF(E74="B-", 2.7, IF(E74="C+", 2.3, IF(E74="C", 2, IF(E74="C-", 1.7, IF(E74="D+", 1.3, IF(E74="D", 1, IF(E74="E", 0, 0))))))))))))) * 3 + (IF(F74="A+", 4, IF(F74="A", 4, IF(F74="A-", 3.7, IF(F74="B+", 3.3, IF(F74="B", 3, IF(F74="B-", 2.7, IF(F74="C+", 2.3, IF(F74="C", 2, IF(F74="C-", 1.7, IF(F74="D+", 1.3, IF(F74="D", 1, IF(F74="E", 0, 0))))))))))))) * 3 + (IF(G74="A+", 4, IF(G74="A", 4, IF(G74="A-", 3.7, IF(G74="B+", 3.3, IF(G74="B", 3, IF(G74="B-", 2.7, IF(G74="C+", 2.3, IF(G74="C", 2, IF(G74="C-", 1.7, IF(G74="D+", 1.3, IF(G74="D", 1, IF(G74="E", 0, 0))))))))))))) * 2) / (4 + 3 + 3 + 3 + 2), 2), 0) -> 3.06
A75: 2020/ICT/86 | B75: Ms. Niwandana N.P.K.M. | C75: B+ | D75: A- | E75: B | F75: C | H75: =IFERROR( ROUND( ( (IF(C75="A+", 4, IF(C75="A", 4, IF(C75="A-", 3.7, IF(C75="B+", 3.3, IF(C75="B", 3, IF(C75="B-", 2.7, IF(C75="C+", 2.3, IF(C75="C", 2, IF(C75="C-", 1.7, IF(C75="D+", 1.3, IF(C75="D", 1, IF(C75="E", 0, 0))))))))))))) * 4 + (IF(D75="A+", 4, IF(D75="A", 4, IF(D75="A-", 3.7, IF(D75="B+", 3.3, IF(D75="B", 3, IF(D75="B-", 2.7, IF(D75="C+", 2.3, IF(D75="C", 2, IF(D75="C-", 1.7, IF(D75="D+", 1.3, IF(D75="D", 1, IF(D75="E", 0, 0))))))))))))) * 3 + (IF(E75="A+", 4, IF(E75="A", 4, IF(E75="A-", 3.7, IF(E75="B+", 3.3, IF(E75="B", 3, IF(E75="B-", 2.7, IF(E75="C+", 2.3, IF(E75="C", 2, IF(E75="C-", 1.7, IF(E75="D+", 1.3, IF(E75="D", 1, IF(E75="E", 0, 0))))))))))))) * 3 + (IF(F75="A+", 4, IF(F75="A", 4, IF(F75="A-", 3.7, IF(F75="B+", 3.3, IF(F75="B", 3, IF(F75="B-", 2.7, IF(F75="C+", 2.3, IF(F75="C", 2, IF(F75="C-", 1.7, IF(F75="D+", 1.3, IF(F75="D", 1, IF(F75="E", 0, 0))))))))))))) * 3 + (IF(G75="A+", 4, IF(G75="A", 4, IF(G75="A-", 3.7, IF(G75="B+", 3.3, IF(G75="B", 3, IF(G75="B-", 2.7, IF(G75="C+", 2.3, IF(G75="C", 2, IF(G75="C-", 1.7, IF(G75="D+", 1.3, IF(G75="D", 1, IF(G75="E", 0, 0))))))))))))) * 2) / (4 + 3 + 3 + 3 + 2), 2), 0) -> 2.62
A76: 2020/ICT/87 | B76: Ms. Jayasundara J.M.G.R. | C76: B | D76: B | E76: B+ | F76: B- | G76: C+ | H76: =IFERROR( ROUND( ( (IF(C76="A+", 4, IF(C76="A", 4, IF(C76="A-", 3.7, IF(C76="B+", 3.3, IF(C76="B", 3, IF(C76="B-", 2.7, IF(C76="C+", 2.3, IF(C76="C", 2, IF(C76="C-", 1.7, IF(C76="D+", 1.3, IF(C76="D", 1, IF(C76="E", 0, 0))))))))))))) * 4 + (IF(D76="A+", 4, IF(D76="A", 4, IF(D76="A-", 3.7, IF(D76="B+", 3.3, IF(D76="B", 3, IF(D76="B-", 2.7, IF(D76="C+", 2.3, IF(D76="C", 2, IF(D76="C-", 1.7, IF(D76="D+", 1.3, IF(D76="D", 1, IF(D76="E", 0, 0))))))))))))) * 3 + (IF(E76="A+", 4, IF(E76="A", 4, IF(E76="A-", 3.7, IF(E76="B+", 3.3, IF(E76="B", 3, IF(E76="B-", 2.7, IF(E76="C+", 2.3, IF(E76="C", 2, IF(E76="C-", 1.7, IF(E76="D+", 1.3, IF(E76="D", 1, IF(E76="E", 0, 0))))))))))))) * 3 + (IF(F76="A+", 4, IF(F76="A", 4, IF(F76="A-", 3.7, IF(F76="B+", 3.3, IF(F76="B", 3, IF(F76="B-", 2.7, IF(F76="C+", 2.3, IF(F76="C", 2, IF(F76="C-", 1.7, IF(F76="D+", 1.3, IF(F76="D", 1, IF(F76="E", 0, 0))))))))))))) * 3 + (IF(G76="A+", 4, IF(G76="A", 4, IF(G76="A-", 3.7, IF(G76="B+", 3.3, IF(G76="B", 3, IF(G76="B-", 2.7, IF(G76="C+", 2.3, IF(G76="C", 2, IF(G76="C-", 1.7, IF(G76="D+", 1.3, IF(G76="D", 1, IF(G76="E", 0, 0))))))))))))) * 2) / (4 + 3 + 3 + 3 + 2), 2), 0) -> 2.91
A77: 2020/ICT/88 | B77: Ms. Perera KNR | C77: B- | D77: C | E77: C | F77: C | G77: C | H77: =IFERROR( ROUND( ( (IF(C77="A+", 4, IF(C77="A", 4, IF(C77="A-", 3.7, IF(C77="B+", 3.3, IF(C77="B", 3, IF(C77="B-", 2.7, IF(C77="C+", 2.3, IF(C77="C", 2, IF(C77="C-", 1.7, IF(C77="D+", 1.3, IF(C77="D", 1, IF(C77="E", 0, 0))))))))))))) * 4 + (IF(D77="A+", 4, IF(D77="A", 4, IF(D77="A-", 3.7, IF(D77="B+", 3.3, IF(D77="B", 3, IF(D77="B-", 2.7, IF(D77="C+", 2.3, IF(D77="C", 2, IF(D77="C-", 1.7, IF(D77="D+", 1.3, IF(D77="D", 1, IF(D77="E", 0, 0))))))))))))) * 3 + (IF(E77="A+", 4, IF(E77="A", 4, IF(E77="A-", 3.7, IF(E77="B+", 3.3, IF(E77="B", 3, IF(E77="B-", 2.7, IF(E77="C+", 2.3, IF(E77="C", 2, IF(E77="C-", 1.7, IF(E77="D+", 1.3, IF(E77="D", 1, IF(E77="E", 0, 0))))))))))))) * 3 + (IF(F77="A+", 4, IF(F77="A", 4, IF(F77="A-", 3.7, IF(F77="B+", 3.3, IF(F77="B", 3, IF(F77="B-", 2.7, IF(F77="C+", 2.3, IF(F77="C", 2, IF(F77="C-", 1.7, IF(F77="D+", 1.3, IF(F77="D", 1, IF(F77="E", 0, 0))))))))))))) * 3 + (IF(G77="A+", 4, IF(G77="A", 4, IF(G77="A-", 3.7, IF(G77="B+", 3.3, IF(G77="B", 3, IF(G77="B-", 2.7, IF(G77="C+", 2.3, IF(G77="C", 2, IF(G77="C-", 1.7, IF(G77="D+", 1.3, IF(G77="D", 1, IF(G77="E", 0, 0))))))))))))) * 2) / (4 + 3 + 3 + 3 + 2), 2), 0) -> 2.19
A78: 2020/ICT/90 | B78: Ms. Madhushani K.M.I.I | C78: B+ | D78: A- | E78: B+ | F78: C+ | G78: B- | H78: =IFERROR( ROUND( ( (IF(C78="A+", 4, IF(C78="A", 4, IF(C78="A-", 3.7, IF(C78="B+", 3.3, IF(C78="B", 3, IF(C78="B-", 2.7, IF(C78="C+", 2.3, IF(C78="C", 2, IF(C78="C-", 1.7, IF(C78="D+", 1.3, IF(C78="D", 1, IF(C78="E", 0, 0))))))))))))) * 4 + (IF(D78="A+", 4, IF(D78="A", 4, IF(D78="A-", 3.7, IF(D78="B+", 3.3, IF(D78="B", 3, IF(D78="B-", 2.7, IF(D78="C+", 2.3, IF(D78="C", 2, IF(D78="C-", 1.7, IF(D78="D+", 1.3, IF(D78="D", 1, IF(D78="E", 0, 0))))))))))))) * 3 + (IF(E78="A+", 4, IF(E78="A", 4, IF(E78="A-", 3.7, IF(E78="B+", 3.3, IF(E78="B", 3, IF(E78="B-", 2.7, IF(E78="C+", 2.3, IF(E78="C", 2, IF(E78="C-", 1.7, IF(E78="D+", 1.3, IF(E78="D", 1, IF(E78="E", 0, 0))))))))))))) * 3 + (IF(F78="A+", 4, IF(F78="A", 4, IF(F78="A-", 3.7, IF(F78="B+", 3.3, IF(F78="B", 3, IF(F78="B-", 2.7, IF(F78="C+", 2.3, IF(F78="C", 2, IF(F78="C-", 1.7, IF(F78="D+", 1.3, IF(F78="D", 1, IF(F78="E", 0, 0))))))))))))) * 3 + (IF(G78="A+", 4, IF(G78="A", 4, IF(G78="A-", 3.7, IF(G78="B+", 3.3, IF(G78="B", 3, IF(G78="B-", 2.7, IF(G78="C+", 2.3, IF(G78="C", 2, IF(G78="C-", 1.7, IF(G78="D+", 1.3, IF(G78="D", 1, IF(G78="E", 0, 0))))))))))))) * 2) / (4 + 3 + 3 + 3 + 2), 2), 0) -> 3.1
A79: 2020/ICT/91 | B79: Ms. Perera H.D.S. | C79: A- | D79: B+ | E79: B+ | F79: B+ | G79: C | H79: =IFERROR( ROUND( ( (IF(C79="A+", 4, IF(C79="A", 4, IF(C79="A-", 3.7, IF(C79="B+", 3.3, IF(C79="B", 3, IF(C79="B-", 2.7, IF(C79="C+", 2.3, IF(C79="C", 2, IF(C79="C-", 1.7, IF(C79="D+", 1.3, IF(C79="D", 1, IF(C79="E", 0, 0))))))))))))) * 4 + (IF(D79="A+", 4, IF(D79="A", 4, IF(D79="A-", 3.7, IF(D79="B+", 3.3, IF(D79="B", 3, IF(D79="B-", 2.7, IF(D79="C+", 2.3, IF(D79="C", 2, IF(D79="C-", 1.7, IF(D79="D+", 1.3, IF(D79="D", 1, IF(D79="E", 0, 0))))))))))))) * 3 + (IF(E79="A+", 4, IF(E79="A", 4, IF(E79="A-", 3.7, IF(E79="B+", 3.3, IF(E79="B", 3, IF(E79="B-", 2.7, IF(E79="C+", 2.3, IF(E79="C", 2, IF(E79="C-", 1.7, IF(E79="D+", 1.3, IF(E79="D", 1, IF(E79="E", 0, 0))))))))))))) * 3 + (IF(F79="A+", 4, IF(F79="A", 4, IF(F79="A-", 3.7, IF(F79="B+", 3.3, IF(F79="B", 3, IF(F79="B-", 2.7, IF(F79="C+", 2.3, IF(F79="C", 2, IF(F79="C-", 1.7, IF(F79="D+", 1.3, IF(F79="D", 1, IF(F79="E", 0, 0))))))))))))) * 3 + (IF(G79="A+", 4, IF(G79="A", 4, IF(G79="A-", 3.7, IF(G79="B+", 3.3, IF(G79="B", 3, IF(G79="B-", 2.7, IF(G79="C+", 2.3, IF(G79="C", 2, IF(G79="C-", 1.7, IF(G79="D+", 1.3, IF(G79="D", 1, IF(G79="E", 0, 0))))))))))))) * 2) / (4 + 3 + 3 + 3 + 2), 2), 0) -> 3.23
A80: 2020/ICT/92 | B80: Mr. Kulathunga M.A.S.S. | C80: A+ | D80: A- | E80: A- | F80: A- | G80: B | H80: =IFERROR( ROUND( ( (IF(C80="A+", 4, IF(C80="A", 4, IF(C80="A-", 3.7, IF(C80="B+", 3.3, IF(C80="B", 3, IF(C80="B-", 2.7, IF(C80="C+", 2.3, IF(C80="C", 2, IF(C80="C-", 1.7, IF(C80="D+", 1.3, IF(C80="D", 1, IF(C80="E", 0, 0))))))))))))) * 4 + (IF(D80="A+", 4, IF(D80="A", 4, IF(D80="A-", 3.7, IF(D80="B+", 3.3, IF(D80="B", 3, IF(D80="B-", 2.7, IF(D80="C+", 2.3, IF(D80="C", 2, IF(D80="C-", 1.7, IF(D80="D+", 1.3, IF(D80="D", 1, IF(D80="E", 0, 0))))))))))))) * 3 + (IF(E80="A+", 4, IF(E80="A", 4, IF(E80="A-", 3.7, IF(E80="B+", 3.3, IF(E80="B", 3, IF(E80="B-", 2.7, IF(E80="C+", 2.3, IF(E80="C", 2, IF(E80="C-", 1.7, IF(E80="D+", 1.3, IF(E80="D", 1, IF(E80="E", 0, 0))))))))))))) * 3 + (IF(F80="A+", 4, IF(F80="A", 4, IF(F80="A-", 3.7, IF(F80="B+", 3.3, IF(F80="B", 3, IF(F80="B-", 2.7, IF(F80="C+", 2.3, IF(F80="C", 2, IF(F80="C-", 1.7, IF(F80="D+", 1.3, IF(F80="D", 1, IF(F80="E", 0, 0))))))))))))) * 3 + (IF(G80="A+", 4, IF(G80="A", 4, IF(G80="A-", 3.7, IF(G80="B+", 3.3, IF(G80="B", 3, IF(G80="B-", 2.7, IF(G80="C+", 2.3, IF(G80="C", 2, IF(G80="C-", 1.7, IF(G80="D+", 1.3, IF(G80="D", 1, IF(G80="E", 0, 0))))))))))))) * 2) / (4 + 3 + 3 + 3 + 2), 2), 0) -> 3.69
A81: 2020/ICT/93 | B81: Mr. Jayathunga R.P. | C81: A+ | D81: A- | E81: A- | F81: A- | G81: B- | H81: =IFERROR( ROUND( ( (IF(C81="A+", 4, IF(C81="A", 4, IF(C81="A-", 3.7, IF(C81="B+", 3.3, IF(C81="B", 3, IF(C81="B-", 2.7, IF(C81="C+", 2.3, IF(C81="C", 2, IF(C81="C-", 1.7, IF(C81="D+", 1.3, IF(C81="D", 1, IF(C81="E", 0, 0))))))))))))) * 4 + (IF(D81="A+", 4, IF(D81="A", 4, IF(D81="A-", 3.7, IF(D81="B+", 3.3, IF(D81="B", 3, IF(D81="B-", 2.7, IF(D81="C+", 2.3, IF(D81="C", 2, IF(D81="C-", 1.7, IF(D81="D+", 1.3, IF(D81="D", 1, IF(D81="E", 0, 0))))))))))))) * 3 + (IF(E81="A+", 4, IF(E81="A", 4, IF(E81="A-", 3.7, IF(E81="B+", 3.3, IF(E81="B", 3, IF(E81="B-", 2.7, IF(E81="C+", 2.3, IF(E81="C", 2, IF(E81="C-", 1.7, IF(E81="D+", 1.3, IF(E81="D", 1, IF(E81="E", 0, 0))))))))))))) * 3 + (IF(F81="A+", 4, IF(F81="A", 4, IF(F81="A-", 3.7, IF(F81="B+", 3.3, IF(F81="B", 3, IF(F81="B-", 2.7, IF(F81="C+", 2.3, IF(F81="C", 2, IF(F81="C-", 1.7, IF(F81="D+", 1.3, IF(F81="D", 1, IF(F81="E", 0, 0))))))))))))) * 3 + (IF(G81="A+", 4, IF(G81="A", 4, IF(G81="A-", 3.7, IF(G81="B+", 3.3, IF(G81="B", 3, IF(G81="B-", 2.7, IF(G81="C+", 2.3, IF(G81="C", 2, IF(G81="C-", 1.7, IF(G81="D+", 1.3, IF(G81="D", 1, IF(G81="E", 0, 0))))))))))))) * 2) / (4 + 3 + 3 + 3 + 2), 2), 0) -> 3.65
A82: 2020/ICT/94 | B82: Ms. Wanninayake P.S. | C82: B- | D82: A- | E82: C+ | F82: C | G82: C+ | H82: =IFERROR( ROUND( ( (IF(C82="A+", 4, IF(C82="A", 4, IF(C82="A-", 3.7, IF(C82="B+", 3.3, IF(C82="B", 3, IF(C82="B-", 2.7, IF(C82="C+", 2.3, IF(C82="C", 2, IF(C82="C-", 1.7, IF(C82="D+", 1.3, IF(C82="D", 1, IF(C82="E", 0, 0))))))))))))) * 4 + (IF(D82="A+", 4, IF(D82="A", 4, IF(D82="A-", 3.7, IF(D82="B+", 3.3, IF(D82="B", 3, IF(D82="B-", 2.7, IF(D82="C+", 2.3, IF(D82="C", 2, IF(D82="C-", 1.7, IF(D82="D+", 1.3, IF(D82="D", 1, IF(D82="E", 0, 0))))))))))))) * 3 + (IF(E82="A+", 4, IF(E82="A", 4, IF(E82="A-", 3.7, IF(E82="B+", 3.3, IF(E82="B", 3, IF(E82="B-", 2.7, IF(E82="C+", 2.3, IF(E82="C", 2, IF(E82="C-", 1.7, IF(E82="D+", 1.3, IF(E82="D", 1, IF(E82="E", 0, 0))))))))))))) * 3 + (IF(F82="A+", 4, IF(F82="A", 4, IF(F82="A-", 3.7, IF(F82="B+", 3.3, IF(F82="B", 3, IF(F82="B-", 2.7, IF(F82="C+", 2.3, IF(F82="C", 2, IF(F82="C-", 1.7, IF(F82="D+", 1.3, IF(F82="D", 1, IF(F82="E", 0, 0))))))))))))) * 3 + (IF(G82="A+", 4, IF(G82="A", 4, IF(G82="A-", 3.7, IF(G82="B+", 3.3, IF(G82="B", 3, IF(G82="B-", 2.7, IF(G82="C+", 2.3, IF(G82="C", 2, IF(G82="C-", 1.7, IF(G82="D+", 1.3, IF(G82="D", 1, IF(G82="E", 0, 0))))))))))))) * 2) / (4 + 3 + 3 + 3 + 2), 2), 0) -> 2.63
A83: 2020/ICT/95 | B83: Ms. Liyanaarachchi W.L.A.D. | C83: A- | D83: B+ | E83: B | F83: B+ | G83: B- | H83: =IFERROR( ROUND( ( (IF(C83="A+", 4, IF(C83="A", 4, IF(C83="A-", 3.7, IF(C83="B+", 3.3, IF(C83="B", 3, IF(C83="B-", 2.7, IF(C83="C+", 2.3, IF(C83="C", 2, IF(C83="C-", 1.7, IF(C83="D+", 1.3, IF(C83="D", 1, IF(C83="E", 0, 0))))))))))))) * 4 + (IF(D83="A+", 4, IF(D83="A", 4, IF(D83="A-", 3.7, IF(D83="B+", 3.3, IF(D83="B", 3, IF(D83="B-", 2.7, IF(D83="C+", 2.3, IF(D83="C", 2, IF(D83="C-", 1.7, IF(D83="D+", 1.3, IF(D83="D", 1, IF(D83="E", 0, 0))))))))))))) * 3 + (IF(E83="A+", 4, IF(E83="A", 4, IF(E83="A-", 3.7, IF(E83="B+", 3.3, IF(E83="B", 3, IF(E83="B-", 2.7, IF(E83="C+", 2.3, IF(E83="C", 2, IF(E83="C-", 1.7, IF(E83="D+", 1.3, IF(E83="D", 1, IF(E83="E", 0, 0))))))))))))) * 3 + (IF(F83="A+", 4, IF(F83="A", 4, IF(F83="A-", 3.7, IF(F83="B+", 3.3, IF(F83="B", 3, IF(F83="B-", 2.7, IF(F83="C+", 2.3, IF(F83="C", 2, IF(F83="C-", 1.7, IF(F83="D+", 1.3, IF(F83="D", 1, IF(F83="E", 0, 0))))))))))))) * 3 + (IF(G83="A+", 4, IF(G83="A", 4, IF(G83="A-", 3.7, IF(G83="B+", 3.3, IF(G83="B", 3, IF(G83="B-", 2.7, IF(G83="C+", 2.3, IF(G83="C", 2, IF(G83="C-", 1.7, IF(G83="D+", 1.3, IF(G83="D", 1, IF(G83="E", 0, 0))))))))))))) * 2) / (4 + 3 + 3 + 3 + 2), 2), 0) -> 3.27
A84: 2020/ICT/96 | B84: Ms Dharmapriya K.S.A. | C84: A+ | D84: B | E84: A | F84: A- | G84: B- | H84: =IFERROR( ROUND( ( (IF(C84="A+", 4, IF(C84="A", 4, IF(C84="A-", 3.7, IF(C84="B+", 3.3, IF(C84="B", 3, IF(C84="B-", 2.7, IF(C84="C+", 2.3, IF(C84="C", 2, IF(C84="C-", 1.7, IF(C84="D+", 1.3, IF(C84="D", 1, IF(C84="E", 0, 0))))))))))))) * 4 + (IF(D84="A+", 4, IF(D84="A", 4, IF(D84="A-", 3.7, IF(D84="B+", 3.3, IF(D84="B", 3, IF(D84="B-", 2.7, IF(D84="C+", 2.3, IF(D84="C", 2, IF(D84="C-", 1.7, IF(D84="D+", 1.3, IF(D84="D", 1, IF(D84="E", 0, 0))))))))))))) * 3 + (IF(E84="A+", 4, IF(E84="A", 4, IF(E84="A-", 3.7, IF(E84="B+", 3.3, IF(E84="B", 3, IF(E84="B-", 2.7, IF(E84="C+", 2.3, IF(E84="C", 2, IF(E84="C-", 1.7, IF(E84="D+", 1.3, IF(E84="D", 1, IF(E84="E", 0, 0))))))))))))) * 3 + (IF(F84="A+", 4, IF(F84="A", 4, IF(F84="A-", 3.7, IF(F84="B+", 3.3, IF(F84="B", 3, IF(F84="B-", 2.7, IF(F84="C+", 2.3, IF(F84="C", 2, IF(F84="C-", 1.7, IF(F84="D+", 1.3, IF(F84="D", 1, IF(F84="E", 0, 0))))))))))))) * 3 + (IF(G84="A+", 4, IF(G84="A", 4, IF(G84="A-", 3.7, IF(G84="B+", 3.3, IF(G84="B", 3, IF(G84="B-", 2.7, IF(G84="C+", 2.3, IF(G84="C", 2, IF(G84="C-", 1.7, IF(G84="D+", 1.3, IF(G84="D", 1, IF(G84="E", 0, 0))))))))))))) * 2) / (4 + 3 + 3 + 3 + 2), 2), 0) -> 3.57
A85: 2020/ICT/97 | B85: Mr. Ponnamperuma N.P. | C85: A+ | D85: A | E85: B | F85: A- | G85: B- | H85: =IFERROR( ROUND( ( (IF(C85="A+", 4, IF(C85="A", 4, IF(C85="A-", 3.7, IF(C85="B+", 3.3, IF(C85="B", 3, IF(C85="B-", 2.7, IF(C85="C+", 2.3, IF(C85="C", 2, IF(C85="C-", 1.7, IF(C85="D+", 1.3, IF(C85="D", 1, IF(C85="E", 0, 0))))))))))))) * 4 + (IF(D85="A+", 4, IF(D85="A", 4, IF(D85="A-", 3.7, IF(D85="B+", 3.3, IF(D85="B", 3, IF(D85="B-", 2.7, IF(D85="C+", 2.3, IF(D85="C", 2, IF(D85="C-", 1.7, IF(D85="D+", 1.3, IF(D85="D", 1, IF(D85="E", 0, 0))))))))))))) * 3 + (IF(E85="A+", 4, IF(E85="A", 4, IF(E85="A-", 3.7, IF(E85="B+", 3.3, IF(E85="B", 3, IF(E85="B-", 2.7, IF(E85="C+", 2.3, IF(E85="C", 2, IF(E85="C-", 1.7, IF(E85="D+", 1.3, IF(E85="D", 1, IF(E85="E", 0, 0))))))))))))) * 3 + (IF(F85="A+", 4, IF(F85="A", 4, IF(F85="A-", 3.7, IF(F85="B+", 3.3, IF(F85="B", 3, IF(F85="B-", 2.7, IF(F85="C+", 2.3, IF(F85="C", 2, IF(F85="C-", 1.7, IF(F85="D+", 1.3, IF(F85="D", 1, IF(F85="E", 0, 0))))))))))))) * 3 + (IF(G85="A+", 4, IF(G85="A", 4, IF(G85="A-", 3.7, IF(G85="B+", 3.3, IF(G85="B", 3, IF(G85="B-", 2.7, IF(G85="C+", 2.3, IF(G85="C", 2, IF(G85="C-", 1.7, IF(G85="D+", 1.3, IF(G85="D", 1, IF(G85="E", 0, 0))))))))))))) * 2) / (4 + 3 + 3 + 3 + 2), 2), 0) -> 3.57
A86: 2020/ICT/98 | B86: Ms. Basnayaka B.M.K.G. | C86: A+ | D86: A | E86: A- | F86: A- | G86: B+ | H86: =IFERROR( ROUND( ( (IF(C86="A+", 4, IF(C86="A", 4, IF(C86="A-", 3.7, IF(C86="B+", 3.3, IF(C86="B", 3, IF(C86="B-", 2.7, IF(C86="C+", 2.3, IF(C86="C", 2, IF(C86="C-", 1.7, IF(C86="D+", 1.3, IF(C86="D", 1, IF(C86="E", 0, 0))))))))))))) * 4 + (IF(D86="A+", 4, IF(D86="A", 4, IF(D86="A-", 3.7, IF(D86="B+", 3.3, IF(D86="B", 3, IF(D86="B-", 2.7, IF(D86="C+", 2.3, IF(D86="C", 2, IF(D86="C-", 1.7, IF(D86="D+", 1.3, IF(D86="D", 1, IF(D86="E", 0, 0))))))))))))) * 3 + (IF(E86="A+", 4, IF(E86="A", 4, IF(E86="A-", 3.7, IF(E86="B+", 3.3, IF(E86="B", 3, IF(E86="B-", 2.7, IF(E86="C+", 2.3, IF(E86="C", 2, IF(E86="C-", 1.7, IF(E86="D+", 1.3, IF(E86="D", 1, IF(E86="E", 0, 0))))))))))))) * 3 + (IF(F86="A+", 4, IF(F86="A", 4, IF(F86="A-", 3.7, IF(F86="B+", 3.3, IF(F86="B", 3, IF(F86="B-", 2.7, IF(F86="C+", 2.3, IF(F86="C", 2, IF(F86="C-", 1.7, IF(F86="D+", 1.3, IF(F86="D", 1, IF(F86="E", 0, 0))))))))))))) * 3 + (IF(G86="A+", 4, IF(G86="A", 4, IF(G86="A-", 3.7, IF(G86="B+", 3.3, IF(G86="B", 3, IF(G86="B-", 2.7, IF(G86="C+", 2.3, IF(G86="C", 2, IF(G86="C-", 1.7, IF(G86="D+", 1.3, IF(G86="D", 1, IF(G86="E", 0, 0))))))))))))) * 2) / (4 + 3 + 3 + 3 + 2), 2), 0) -> 3.79
A87: 2020/ICT/99 | B87: Mr. P. R. Hettiarachchi | C87: C | D87: C+ | E87: D | F87: B- | G87: C+ | H87: =IFERROR( ROUND( ( (IF(C87="A+", 4, IF(C87="A", 4, IF(C87="A-", 3.7, IF(C87="B+", 3.3, IF(C87="B", 3, IF(C87="B-", 2.7, IF(C87="C+", 2.3, IF(C87="C", 2, IF(C87="C-", 1.7, IF(C87="D+", 1.3, IF(C87="D", 1, IF(C87="E", 0, 0))))))))))))) * 4 + (IF(D87="A+", 4, IF(D87="A", 4, IF(D87="A-", 3.7, IF(D87="B+", 3.3, IF(D87="B", 3, IF(D87="B-", 2.7, IF(D87="C+", 2.3, IF(D87="C", 2, IF(D87="C-", 1.7, IF(D87="D+", 1.3, IF(D87="D", 1, IF(D87="E", 0, 0))))))))))))) * 3 + (IF(E87="A+", 4, IF(E87="A", 4, IF(E87="A-", 3.7, IF(E87="B+", 3.3, IF(E87="B", 3, IF(E87="B-", 2.7, IF(E87="C+", 2.3, IF(E87="C", 2, IF(E87="C-", 1.7, IF(E87="D+", 1.3, IF(E87="D", 1, IF(E87="E", 0, 0))))))))))))) * 3 + (IF(F87="A+", 4, IF(F87="A", 4, IF(F87="A-", 3.7, IF(F87="B+", 3.3, IF(F87="B", 3, IF(F87="B-", 2.7, IF(F87="C+", 2.3, IF(F87="C", 2, IF(F87="C-", 1.7, IF(F87="D+", 1.3, IF(F87="D", 1, IF(F87="E", 0, 0))))))))))))) * 3 + (IF(G87="A+", 4, IF(G87="A", 4, IF(G87="A-", 3.7, IF(G87="B+", 3.3, IF(G87="B", 3, IF(G87="B-", 2.7, IF(G87="C+", 2.3, IF(G87="C", 2, IF(G87="C-", 1.7, IF(G87="D+", 1.3, IF(G87="D", 1, IF(G87="E", 0, 0))))))))))))) * 2) / (4 + 3 + 3 + 3 + 2), 2), 0) -> 2.04
... A108: 2020/ICT/120 | B108: Ms.Thavarajah H | C108: A- | D108: A- | E108: B | F108: B | G108: B | H108: =IFERROR( ROUND( ( (IF(C108="A+", 4, IF(C108="A", 4, IF(C108="A-", 3.7, IF(C108="B+", 3.3, IF(C108="B", 3, IF(C108="B-", 2.7, IF(C108="C+", 2.3, IF(C108="C", 2, IF(C108="C-", 1.7, IF(C108="D+", 1.3, IF(C108="D", 1, IF(C108="E", 0, 0))))))))))))) * 4 + (IF(D108="A+", 4, IF(D108="A", 4, IF(D108="A-", 3.7, IF(D108="B+", 3.3, IF(D108="B", 3, IF(D108="B-", 2.7, IF(D108="C+", 2.3, IF(D108="C", 2, IF(D108="C-", 1.7, IF(D108="D+", 1.3, IF(D108="D", 1, IF(D108="E", 0, 0))))))))))))) * 3 + (IF(E108="A+", 4, IF(E108="A", 4, IF(E108="A-", 3.7, IF(E108="B+", 3.3, IF(E108="B", 3, IF(E108="B-", 2.7, IF(E108="C+", 2.3, IF(E108="C", 2, IF(E108="C-", 1.7, IF(E108="D+", 1.3, IF(E108="D", 1, IF(E108="E", 0, 0))))))))))))) * 3 + (IF(F108="A+", 4, IF(F108="A", 4, IF(F108="A-", 3.7, IF(F108="B+", 3.3, IF(F108="B", 3, IF(F108="B-", 2.7, IF(F108="C+", 2.3, IF(F108="C", 2, IF(F108="C-", 1.7, IF(F108="D+", 1.3, IF(F108="D", 1, IF(F108="E", 0, 0))))))))))))) * 3 + (IF(G108="A+", 4, IF(G108="A", 4, IF(G108="A-", 3.7, IF(G108="B+", 3.3, IF(G108="B", 3, IF(G108="B-", 2.7, IF(G108="C+", 2.3, IF(G108="C", 2, IF(G108="C-", 1.7, IF(G108="D+", 1.3, IF(G108="D", 1, IF(G108="E", 0, 0))))))))))))) * 2) / (4 + 3 + 3 + 3 + 2), 2), 0) -> 3.33

Sheet 2.2
A1: Reg.No | B1: Name | C1: IT2244 | D1: IT2234 | E1: IT2223 | F1: IT2212 | G1: IT2252 | H1: GPA
A2: 2020/ICT/01 | B2: Ms. Udisha W.H.I | C2: B | D2: C | E2: C | F2: A- | G2: B- | H2: =#VALUE! -> #VALUE!
A3: 2020/ICT/02 | B3: Mr. Imran B.M. | C3: absent | D3: absent | E3: absent | F3: absent | G3: absent | H3: =#VALUE! -> #VALUE!
A4: 2020/ICT/03 | B4: Ms. Shanmugarajah D. | C4: A- | D4: C+ | E4: C | F4: B- | G4: C+ | H4: =#VALUE! -> #VALUE!
A5: 2020/ICT/05 | B5: Mr. Muniweera K.G.U.K. | C5: B+ | D5: C+ | E5: C | F5: B | G5: B- | H5: =#VALUE! -> #VALUE!
A6: 2020/ICT/06 | B6: Ms. Lourdes Jellorine | C6: A+ | D6: B | E6: B | F6: A | G6: B+ | H6: =#VALUE! -> #VALUE!
A7: 2020/ICT/07 | B7: Mr. Nalawansa U.K | C7: A+ | D7: A- | E7: B- | F7: A | G7: A+ | H7: =#VALUE! -> #VALUE!
A8: 2020/ICT/08 | B8: Ms. Devakumar P. | C8: B | D8: C- | E8: C | F8: C | G8: C | H8: =#VALUE! -> #VALUE!
A9: 2020/ICT/09 | B9: Ms. Senevirathne S.A. | C9: C | D9: C- | E9: C- | F9: B+ | G9: B- | H9: =#VALUE! -> #VALUE!
A10: 2020/ICT/10 | B10: Ms. Jegatheeswaran V. | C10: B+ | D10: C | E10: C | F10: B+ | G10: A- | H10: =#VALUE! -> #VALUE!
A11: 2020/ICT/12 | B11: Ms. Shahla A.A.F.S. | C11: B+ | D11: C+ | E11: C | F11: B- | G11: B | H11: =#VALUE! -> #VALUE!
A12: 2020/ICT/13 | B12: Ms. Basheery M.K.T. | C12: B | D12: C | E12: C | F12: B | G12: B- | H12: =#VALUE! -> #VALUE!
A13: 2020/ICT/14 | B13: Ms. Minha M.S.F. | C13: B+ | D13: C+ | E13: C- | F13: C- | G13: B- | H13: =#VALUE! -> #VALUE!
... A68: 2020/ICT/77 | B68: Ms. Nifra A.H.F. | C68: B+ | D68: C | E68: C | F68: B | G68: A- | H68: =#VALUE! -> #VALUE!
A69: 2020/ICT/79 | B69: Mr. Midun S. | C69: C- | D69: C | E69: C | F69: B+ | G69: A+ | H69: =IFERROR( ROUND( ( (IF(C2="A+", 4, IF(C2="A", 4, IF(C2="A-", 3.7, IF(C2="B+", 3.3, IF(C2="B", 3, IF(C2="B-", 2.7, IF(C2="C+", 2.3, IF(C2="C", 2, IF(C2="C-", 1.7, IF(C2="D+", 1.3, IF(C2="D", 1, IF(C2="E", 0, 0))))))))))))) * 3 + (IF(D2="A+", 4, IF(D2="A", 4, IF(D2="A-", 3.7, IF(D2="B+", 3.3, IF(D2="B", 3, IF(D2="B-", 2.7, IF(D2="C+", 2.3, IF(D2="C", 2, IF(D2="C-", 1.7, IF(D2="D+", 1.3, IF(D2="D", 1, IF(D2="E", 0, 0))))))))))))) * 3 + (IF(E2="A+", 4, IF(E2="A", 4, IF(E2="A-", 3.7, IF(E2="B+", 3.3, IF(E2="B", 3, IF(E2="B-", 2.7, IF(E2="C+", 2.3, IF(E2="C", 2, IF(E2="C-", 1.7, IF(E2="D+", 1.3, IF(E2="D", 1, IF(E2="E", 0, 0))))))))))))) * 3 + (IF(F2="A+", 4, IF(F2="A", 4, IF(F2="A-", 3.7, IF(F2="B+", 3.3, IF(F2="B", 3, IF(F2="B-", 2.7, IF(F2="C+", 2.3, IF(F2="C", 2, IF(F2="C-", 1.7, IF(F2="D+", 1.3, IF(F2="D", 1, IF(F2="E", 0, 0))))))))))))) * 2 + (IF(G2="A+", 4, IF(G2="A", 4, IF(G2="A-", 3.7, IF(G2="B+", 3.3, IF(G2="B", 3, IF(G2="B-", 2.7, IF(G2="C+", 2.3, IF(G2="C", 2, IF(G2="C-", 1.7, IF(G2="D+", 1.3, IF(G2="D", 1, IF(G2="E", 0, 0))))))))))))) * 2 + (IF(H2="A+", 4, IF(H2="A", 4, IF(H2="A-", 3.7, IF(H2="B+", 3.3, IF(H2="B", 3, IF(H2="B-", 2.7, IF(H2="C+", 2.3, IF(H2="C", 2, IF(H2="C-", 1.7, IF(H2="D+", 1.3, IF(H2="D", 1, IF(H2="E", 0, 0))))))))))))) * 2 ) / (3 + 3 + 3 + 2 + 2 + 2), 2), 0) -> 0
A70: 2020/ICT/80 | B70: Ms. Insafa K.R. | C70: D | D70: C- | E70: D+ | F70: C+ | G70: C | H70: =#VALUE! -> #VALUE!
A71: 2020/ICT/81 | B71: Ms. Shakeeka S.F. | C71: C+ | D71: C- | E71: D | F71: C+ | G71: B | H71: =#VALUE! -> #VALUE!
A72: 2020/ICT/82 | B72: Ms. Ruzla M.j. | C72: A | D72: B | E72: C+ | F72: B | G72: A | H72: =#VALUE! -> #VALUE!
A73: 2020/ICT/83 | B73: Ms. Lakshna G. | C73: absent | D73: absent | E73: absent | F73: absent | G73: absent | H73: =#VALUE! -> #VALUE!
A74: 2020/ICT/85 | B74: Ms. Gunarathna P.M.D.P.R.P. | C74: B | D74: C- | E74: B- | F74: B | G74: C+ | H74: =#VALUE! -> #VALUE!
A75: 2020/ICT/86 | B75: Ms. Niwandana N.P.K.M. | C75: B | D75: D+ | E75: B- | F75: B- | G75: C+ | H75: =#VALUE! -> #VALUE!
A76: 2020/ICT/87 | B76: Ms. Jayasundara J.M.G.R. | C76: C+ | D76: C | E76: C | F76: B | G76: C | H76: =#VALUE! -> #VALUE!
A77: 2020/ICT/88 | B77: Ms. Perera KNR | C77: C+ | D77: C- | E77: D | F77: C+ | G77: C- | H77: =#VALUE! -> #VALUE!
A78: 2020/ICT/90 | B78: Ms. Madhushani K.M.I.I | C78: A- | D78: C | E78: C+ | F78: B+ | G78: C+ | H78: =#VALUE! -> #VALUE!
A79: 2020/ICT/91 | B79: Ms. Perera H.D.S. | C79: A+ | D79: C | E79: B- | F79: B | G79: B- | H79: =#VALUE! -> #VALUE!
A80: 2020/ICT/92 | B80: Mr. Kulathunga M.A.S.S. | C80: A | D80: B | E80: B- | F80: A- | G80: A | H80: =#VALUE! -> #VALUE!
A81: 2020/ICT/93 | B81: Mr. Jayathunga R.P. | C81: A | D81: C- | E81: C+ | F81: B- | G81: B | H81: =#VALUE! -> #VALUE!
... A108: 2020/ICT/120 | B108: Ms.Thavarajah H | C108: B+ | D108: C | E108: C+ | F108: B | G108: B- | H108: =#VALUE! -> #VALUE!

Sheet 3.1
A1: Reg.No | B1: Name | C1: IT3113 | D1: IT3133 | E1: IT3143 | F1: IT3122 | G1: IT3152 | H1: IT3162 | I1: GPA
A2: 2020/ICT/01 | B2: Ms. Udisha W.H.I | C2: B+ | D2: C+ | E2: A- | F2: C+ | G2: B+ | H2: A- | I2: =IFERROR( ROUND( ( (IF(C2="A+", 4, IF(C2="A", 4, IF(C2="A-", 3.7, IF(C2="B+", 3.3, IF(C2="B", 3, IF(C2="B-", 2.7, IF(C2="C+", 2.3, IF(C2="C", 2, IF(C2="C-", 1.7, IF(C2="D+", 1.3, IF(C2="D", 1, IF(C2="E", 0, 0))))))))))))) * 3 + (IF(D2="A+", 4, IF(D2="A", 4, IF(D2="A-", 3.7, IF(D2="B+", 3.3, IF(D2="B", 3, IF(D2="B-", 2.7, IF(D2="C+", 2.3, IF(D2="C", 2, IF(D2="C-", 1.7, IF(D2="D+", 1.3, IF(D2="D", 1, IF(D2="E", 0, 0))))))))))))) * 3 + (IF(E2="A+", 4, IF(E2="A", 4, IF(E2="A-", 3.7, IF(E2="B+", 3.3, IF(E2="B", 3, IF(E2="B-", 2.7, IF(E2="C+", 2.3, IF(E2="C", 2, IF(E2="C-", 1.7, IF(E2="D+", 1.3, IF(E2="D", 1, IF(E2="E", 0, 0))))))))))))) * 3 + (IF(F2="A+", 4, IF(F2="A", 4, IF(F2="A-", 3.7, IF(F2="B+", 3.3, IF(F2="B", 3, IF(F2="B-", 2.7, IF(F2="C+", 2.3, IF(F2="C", 2, IF(F2="C-", 1.7, IF(F2="D+", 1.3, IF(F2="D", 1, IF(F2="E", 0, 0))))))))))))) * 2 + (IF(G2="A+", 4, IF(G2="A", 4, IF(G2="A-", 3.7, IF(G2="B+", 3.3, IF(G2="B", 3, IF(G2="B-", 2.7, IF(G2="C+", 2.3, IF(G2="C", 2, IF(G2="C-", 1.7, IF(G2="D+", 1.3, IF(G2="D", 1, IF(G2="E", 0, 0))))))))))))) * 2 + (IF(H2="A+", 4, IF(H2="A", 4, IF(H2="A-", 3.7, IF(H2="B+", 3.3, IF(H2="B", 3, IF(H2="B-", 2.7, IF(H2="C+", 2.3, IF(H2="C", 2, IF(H2="C-", 1.7, IF(H2="D+", 1.3, IF(H2="D", 1, IF(H2="E", 0, 0))))))))))))) * 2 ) / (3 + 3 + 3 + 2 + 2 + 2), 2), 0) -> 3.1
